Workbook
Name _666三听: 技能数计算!$AS$6
Name delta攻击: 属性常数!$B$27
Name delta会效: 属性常数!$B$31
Name delta会心: 属性常数!$B$30
Name delta破防: 属性常数!$B$32
Name delta破招: 属性常数!$B$33
Name delta身法: 属性常数!$B$29
Name delta无双: 属性常数!$B$34
Name delta武伤: 属性常数!$B$28
Name 碧归: 技能数据库!$M$40
Name 残雪: 技能数据库!$M$41
Name 层云: 技能数据库!$M$42
Name 橙武补雾锁: 技能数计算!$AN$66
Name 创意食品: 额外属性!$C$66:$C$69
Name 创意食品减益: 额外属性!$C$63:$C$65
Name 次等蓝色无双: 附魔库!$K$12
Name 次等挑战紫色攻击: 附魔库!$E$6
Name 次等挑战紫色身法: 附魔库!$E$8
Name 次等挑战紫色体质: 附魔库!$E$9
Name 次等挑战紫色通用: 附魔库!$E$7
Name 次等紫色攻击: 附魔库!$I$6
Name 次等紫色气血: 附魔库!$I$10
Name 次等紫色身法: 附魔库!$I$8
Name 次等紫色体质: 附魔库!$I$9
Name 次等紫色通用: 附魔库!$I$7
Name 次等紫色武器伤害: 附魔库!$I$11
Name 岱宗: 技能数据库!$M$43
Name 等级系数130: 属性常数!$G$12
Name 等级系数131: 属性常数!$G$13
Name 等级系数132: 属性常数!$G$14
Name 等级系数133: 属性常数!$G$15
Name 等级系数134: 属性常数!$G$16
Name 第一属性: 镶嵌库!$E$30:$E$39
Name 叠峰意: 技能数据库!$M$73
Name 二属性攻击: 镶嵌库!$H$30:$H$35
Name 二属性会效: 镶嵌库!$K$30:$K$34
Name 二属性会心: 镶嵌库!$J$30:$J$32
Name 二属性加速: 镶嵌库!$O$30:$O$32
Name 二属性精简: 镶嵌库!$N$30
Name 二属性破防: 镶嵌库!$I$30:$I$34
Name 二属性破招: 镶嵌库!$L$30:$L$33
Name 二属性身法: 镶嵌库!$G$30:$G$33
Name 二属性无双: 镶嵌库!$M$30:$M$33
Name 二属性武器伤害: 镶嵌库!$P$30:$P$34
Name 飞来闻踪: 技能数据库!$M$44
Name 非侠士伤害: 属性常数!$B$25
Name 风车GCD: 加速!$E$15
Name 风来2会: 技能数据库!$M$21
Name 风来2伤: 技能数据库!$M$19
Name 风来3会: 技能数据库!$M$20
Name 风来3伤: 技能数据库!$M$18
Name 风来4伤: 技能数据库!$M$17
Name 风来秘籍: 技能数据库!$M$17:$M$21
Name 攻击系数库: 技能数据库!$G$2:$G$500
Name 固定伤害库: 技能数据库!$C$2:$C$500
Name 撼岳: 技能数据库!$M$45
Name 鹤归_CD1: 技能数据库!$M$33
Name 鹤归_CD2: 技能数据库!$M$34
Name 鹤归2会: 技能数据库!$M$38
Name 鹤归3伤: 技能数据库!$M$37

Sheet 属性常数
A1: 字段 | B1: 属性 | C1: 全局系数 | D1: 130级系数 | F1: 等级 | G1: 等级常数
A2: fCriticalStrikeParam | B2: 会心 | C2: 9.985 | D2: =C2*$G$12 -> 197703 | F2: 120 | G2: =1155*F2-130350 -> 8250
A3: fCriticalStrikePowerParam | B3: 会效 | C3: 3.679 | D3: =C3*$G$12 -> 72844.2 | F3: 121 | G3: =1155*F3-130350 -> 9405
A4: fDefCriticalStrikeParam | B4: 御劲 | C4: 9.985 | D4: =C4*$G$12 -> 197703 | F4: 122 | G4: =1155*F4-130350 -> 10560
A5: fDecriticalStrikePowerParam | B5: 化劲 | C5: 1.669 | D5: =C5*$G$12 -> 33046.2 | F5: 123 | G5: =1155*F5-130350 -> 11715
A6: fHitValueParam | B6: 命中 | C6: 7.644 | D6: =C6*$G$12 -> 151351.2 | F6: 124 | G6: =1155*F6-130350 -> 12870
A7: fDodgeParam | B7: 闪避 | C7: 4.628 | D7: =C7*$G$12 -> 91634.4 | F7: 125 | G7: =1155*F7-130350 -> 14025
A8: fParryParam | B8: 招架 | C8: 5.432 | D8: =C8*$G$12 -> 107553.6 | F8: 126 | G8: =1155*F8-130350 -> 15180
A9: fInsightParam | B9: 无双 | C9: 6.734 | D9: =C9*$G$12 -> 133333.2 | F9: 127 | G9: =1155*F9-130350 -> 16335
A10: fPhysicsShieldParam | B10: 外防 | C10: 6.364 | D10: =C10*$G$12 -> 126007.2 | F10: 128 | G10: =1155*F10-130350 -> 17490
A11: fMagicShieldParam | B11: 内防 | C11: 6.364 | D11: =C11*$G$12 -> 126007.2 | F11: 129 | G11: =1155*F11-130350 -> 18645
A12: fOvercomeParam | B12: 破防 | C12: 11.412 | D12: =C12*$G$12 -> 225957.6 | F12: 130 | G12: =1155*F12-130350 -> 19800
A13: fHasteRate | B13: 急速 | C13: 10.61 | D13: =C13*$G$12 -> 210078 | F13: 131 | G13: =1155*F13-130350 -> 20955
A14: fToughnessDecirDamageCof | B14: 御劲减会伤 | C14: 2.784 | D14: =C14*$G$12 -> 55123.2 | F14: 132 | G14: =1155*F14-130350 -> 22110
A15: fSurplusParam | B15: 破招 | C15: 8.534 | F15: 133 | G15: =1155*F15-130350 -> 23265
F16: 134 | G16: =1155*F16-130350 -> 24420
A18: 力道转基础攻击 | B18: 0.163
A19: 力道转基础破防 | B19: 0.3
A20: 身法转基础会心 | B20: 0.9
A21: 身法转额外攻击 | B21: =C21/1024 -> 1.7998047 | C21: 1843
A22: 身法转额外破防 | B22: =C22/1024 -> 0.28027344 | C22: 287
A23: 全能转无双 | B23: 1.5
A24: 全能转破招 | B24: 0.5
A25: 非侠士伤害 | B25: 154
A26: delta是否启用 | C26: 1 | E26: 陆级五彩石1 | F26: 附魔 | G26: 8级五行石 | H26: 同分
A27: delta攻击 | B27: =$C$26*C27 -> 397 | C27: =INDEX($E$27:$H$34,ROW()-ROW($C$26),IFERROR(MATCH(配装计算器!$N$2,属性常数!$E$26:$H$26,0),1)) -> 397 | E27: 397 | F27: 652 | G27: 260 | H27: 24.890447
A28: delta武伤 | B28: =$C$26*C28 -> 596.25 | C28: =INDEX($E$27:$H$34,ROW()-ROW($C$26),IFERROR(MATCH(配装计算器!$N$2,属性常数!$E$26:$H$26,0),1)) -> 596.25 | E28: =2385/4 -> 596.25 | F28: 984 | G28: 391 | H28: 37.510955
A29: delta身法 | B29: =$C$26*C29 -> 188 | C29: =INDEX($E$27:$H$34,ROW()-ROW($C$26),IFERROR(MATCH(配装计算器!$N$2,属性常数!$E$26:$H$26,0),1)) -> 188 | E29: 188 | F29: 308 | G29: 122 | H29: 11.744084
A30: delta会心 | B30: =$C$26*C30 -> 1463 | C30: =INDEX($E$27:$H$34,ROW()-ROW($C$26),IFERROR(MATCH(配装计算器!$N$2,属性常数!$E$26:$H$26,0),1)) -> 1463 | E30: 1463 | F30: 2401 | G30: 960 | H30: 91.542507
A31: delta会效 | B31: =$C$26*C31 -> 1463 | C31: =INDEX($E$27:$H$34,ROW()-ROW($C$26),IFERROR(MATCH(配装计算器!$N$2,属性常数!$E$26:$H$26,0),1)) -> 1463 | E31: 1463 | F31: 2401 | G31: 960 | H31: 91.542507
A32: delta破防 | B32: =$C$26*C32 -> 1463 | C32: =INDEX($E$27:$H$34,ROW()-ROW($C$26),IFERROR(MATCH(配装计算器!$N$2,属性常数!$E$26:$H$26,0),1)) -> 1463 | E32: 1463 | F32: 2401 | G32: 960 | H32: 91.542507
A33: delta破招 | B33: =$C$26*C33 -> 1463 | C33: =INDEX($E$27:$H$34,ROW()-ROW($C$26),IFERROR(MATCH(配装计算器!$N$2,属性常数!$E$26:$H$26,0),1)) -> 1463 | E33: 1463 | F33: 2401 | G33: 960 | H33: 91.542507
A34: delta无双 | B34: =$C$26*C34 -> 1463 | C34: =INDEX($E$27:$H$34,ROW()-ROW($C$26),IFERROR(MATCH(配装计算器!$N$2,属性常数!$E$26:$H$26,0),1)) -> 1463 | E34: 1463 | F34: 2401 | G34: 960 | H34: 91.542507
A36: 自输入属性 | B36: =IFERROR(COUNTIF(配装计算器!R4,属性常数!A36),0) -> 0
A37: 内置配装器 | B37: =1-B36 -> 1

Sheet 装备库
A1: 部位 | B1: 装备ID | C1: 装备名称 | D1: 装备等级 | E1: 显示名称 | F1: 体质 | G1: 身法 | H1: 力道 | I1: 攻击 | J1: 会心 | K1: 会效 | L1: 破防 | M1: 破招 | N1: 无双 | O1: 加速 | P1: 全能 | Q1: 御劲 | R1: 武器伤害 | S1: 武器伤害2 | T1: 简称 | U1: 最大可精炼等级 | V1: 装备来源 | W1: 孔1 | X1: 孔2 | Y1: 孔3 | Z1: PVE装备 | AA1: 品级 | AB1: 会心 | AC1: 会效 | AD1: 破防 | AE1: 破招 | AF1: 无双 | AG1: 加速 | AH1: 全能 | AI1: 精简 | AJ1: 筛选结果 | AK1: 累计装备数 | AQ1: 会心 | AR1: 会效 | AS1: 破防 | AT1: 破招 | AU1: 无双 | AV1: 加速 | AW1: 全能 | AX1: 精简
A2: 暗器 | B2: 6_43603 | C2: 智渊囊 | D2: 30200 | E2: 智渊囊(30200破全) | F2: 9948 | G2: 754 | I2: 1229 | J2: 0 | K2: 0 | L2: 6783 | M2: 0 | N2: 0 | O2: 0 | P2: 2713 | R2: 0 | S2: 0 | T2: 破全 | U2: 6 | V2: 副本 | W2: 身法孔 | Z2: 2 | AA2: =IF(AND(D2>=配装计算器!$I$29,D2<=配装计算器!$I$30),1,0) -> 1 | AB2: =IF(J2>0,1,0) -> 0 | AC2: =IF(K2>0,1,0) -> 0 | AD2: =IF(L2>0,1,0) -> 1 | AE2: =IF(M2>0,1,0) -> 0 | AF2: =IF(N2>0,1,0) -> 0 | AG2: =IF(O2>0,1,0) -> 0 | AH2: =IF(P2>0,1,0) -> 1 | AI2: =IF(COUNTIF(T2,"*"&"精简"&"*")>0,1,0) -> 0 | AJ2: =MIN(1,AA2*($AY$2+IF(AND(AB2>=$AQ$3,AC2>=$AR$3,AD2>=$AS$3,AE2>=$AT$3,AF2>=$AU$3,AG2>=$AV$3,AH2>=$AW$3,AI2>=$AX$3),1,0))) -> 1 | AK2: =SUM(AJ$2:$AJ2) -> 1 | AQ2: FALSE | AR2: FALSE | AS2: FALSE | AT2: FALSE | AU2: FALSE | AV2: FALSE | AW2: FALSE | AX2: FALSE | AY2: =IF(SUM(AQ3:AX3)=0,1,0) -> 1
A3: 暗器 | B3: 6_43641 | C3: 镂云囊 | D3: 30200 | E3: 镂云囊(30200会全) | F3: 9948 | G3: 754 | I3: 1229 | J3: 6783 | K3: 0 | L3: 0 | M3: 0 | N3: 0 | O3: 0 | P3: 2713 | R3: 0 | S3: 0 | T3: 会全 | U3: 6 | V3: 副本 | W3: 会心孔 | Z3: 2 | AA3: =IF(AND(D3>=配装计算器!$I$29,D3<=配装计算器!$I$30),1,0) -> 1 | AB3: =IF(J3>0,1,0) -> 1 | AC3: =IF(K3>0,1,0) -> 0 | AD3: =IF(L3>0,1,0) -> 0 | AE3: =IF(M3>0,1,0) -> 0 | AF3: =IF(N3>0,1,0) -> 0 | AG3: =IF(O3>0,1,0) -> 0 | AH3: =IF(P3>0,1,0) -> 1 | AI3: =IF(COUNTIF(T3,"*"&"精简"&"*")>0,1,0) -> 0 | AJ3: =MIN(1,AA3*($AY$2+IF(AND(AB3>=$AQ$3,AC3>=$AR$3,AD3>=$AS$3,AE3>=$AT$3,AF3>=$AU$3,AG3>=$AV$3,AH3>=$AW$3,AI3>=$AX$3),1,0))) -> 1 | AK3: =SUM(AJ$2:$AJ3) -> 2 | AQ3: =INT(AQ2) -> 0 | AR3: =INT(AR2) -> 0 | AS3: =INT(AS2) -> 0 | AT3: =INT(AT2) -> 0 | AU3: =INT(AU2) -> 0 | AV3: =INT(AV2) -> 0 | AW3: =INT(AW2) -> 0 | AX3: =INT(AX2) -> 0
A4: 暗器 | B4: 6_45633 | C4: 臻泽囊 | D4: 30200 | E4: 臻泽囊(30200会全) | F4: 9948 | G4: 754 | I4: 1229 | J4: 6783 | K4: 0 | L4: 0 | M4: 0 | N4: 0 | O4: 0 | P4: 2713 | R4: 0 | S4: 0 | T4: 会全 | U4: 6 | V4: 活动 | W4: 会心孔 | Z4: 2 | AA4: =IF(AND(D4>=配装计算器!$I$29,D4<=配装计算器!$I$30),1,0) -> 1 | AB4: =IF(J4>0,1,0) -> 1 | AC4: =IF(K4>0,1,0) -> 0 | AD4: =IF(L4>0,1,0) -> 0 | AE4: =IF(M4>0,1,0) -> 0 | AF4: =IF(N4>0,1,0) -> 0 | AG4: =IF(O4>0,1,0) -> 0 | AH4: =IF(P4>0,1,0) -> 1 | AI4: =IF(COUNTIF(T4,"*"&"精简"&"*")>0,1,0) -> 0 | AJ4: =MIN(1,AA4*($AY$2+IF(AND(AB4>=$AQ$3,AC4>=$AR$3,AD4>=$AS$3,AE4>=$AT$3,AF4>=$AU$3,AG4>=$AV$3,AH4>=$AW$3,AI4>=$AX$3),1,0))) -> 1 | AK4: =SUM(AJ$2:$AJ4) -> 3
A5: 暗器 | B5: 6_43372 | C5: 孤城惊梦·迷烟囊 | D5: 30200 | E5: 孤城惊梦·迷烟囊(30200会无) | F5: 9948 | G5: 812 | I5: 1843 | J5: 6783 | K5: 0 | L5: 0 | M5: 0 | N5: 5426 | O5: 0 | P5: 0 | R5: 0 | S5: 0 | T5: 会无 | U5: 6 | V5: 飞沙令 | W5: 会心孔 | Z5: 1 | AA5: =IF(AND(D5>=配装计算器!$I$29,D5<=配装计算器!$I$30),1,0) -> 1 | AB5: =IF(J5>0,1,0) -> 1 | AC5: =IF(K5>0,1,0) -> 0 | AD5: =IF(L5>0,1,0) -> 0 | AE5: =IF(M5>0,1,0) -> 0 | AF5: =IF(N5>0,1,0) -> 1 | AG5: =IF(O5>0,1,0) -> 0 | AH5: =IF(P5>0,1,0) -> 0 | AI5: =IF(COUNTIF(T5,"*"&"精简"&"*")>0,1,0) -> 0 | AJ5: =MIN(1,AA5*($AY$2+IF(AND(AB5>=$AQ$3,AC5>=$AR$3,AD5>=$AS$3,AE5>=$AT$3,AF5>=$AU$3,AG5>=$AV$3,AH5>=$AW$3,AI5>=$AX$3),1,0))) -> 1 | AK5: =SUM(AJ$2:$AJ5) -> 4
A6: 暗器 | B6: 6_40579 | C6: 羽缀囊 | D6: 30200 | E6: 羽缀囊(30200招无) | F6: 9948 | G6: 812 | I6: 1843 | J6: 0 | K6: 0 | L6: 0 | M6: 6783 | N6: 5426 | O6: 0 | P6: 0 | R6: 0 | S6: 0 | T6: 招无 | U6: 6 | V6: 副本 | W6: 无双孔 | Z6: 1 | AA6: =IF(AND(D6>=配装计算器!$I$29,D6<=配装计算器!$I$30),1,0) -> 1 | AB6: =IF(J6>0,1,0) -> 0 | AC6: =IF(K6>0,1,0) -> 0 | AD6: =IF(L6>0,1,0) -> 0 | AE6: =IF(M6>0,1,0) -> 1 | AF6: =IF(N6>0,1,0) -> 1 | AG6: =IF(O6>0,1,0) -> 0 | AH6: =IF(P6>0,1,0) -> 0 | AI6: =IF(COUNTIF(T6,"*"&"精简"&"*")>0,1,0) -> 0 | AJ6: =MIN(1,AA6*($AY$2+IF(AND(AB6>=$AQ$3,AC6>=$AR$3,AD6>=$AS$3,AE6>=$AT$3,AF6>=$AU$3,AG6>=$AV$3,AH6>=$AW$3,AI6>=$AX$3),1,0))) -> 1 | AK6: =SUM(AJ$2:$AJ6) -> 5
A7: 暗器 | B7: 6_41292 | C7: 焚膏继晷 | D7: 30200 | E7: 焚膏继晷(30200招无) | F7: 9948 | G7: 812 | I7: 1843 | J7: 0 | K7: 0 | L7: 0 | M7: 6783 | N7: 5426 | O7: 0 | P7: 0 | R7: 0 | S7: 0 | T7: 招无 | U7: 6 | V7: 副本 | W7: 无双孔 | Z7: 1 | AA7: =IF(AND(D7>=配装计算器!$I$29,D7<=配装计算器!$I$30),1,0) -> 1 | AB7: =IF(J7>0,1,0) -> 0 | AC7: =IF(K7>0,1,0) -> 0 | AD7: =IF(L7>0,1,0) -> 0 | AE7: =IF(M7>0,1,0) -> 1 | AF7: =IF(N7>0,1,0) -> 1 | AG7: =IF(O7>0,1,0) -> 0 | AH7: =IF(P7>0,1,0) -> 0 | AI7: =IF(COUNTIF(T7,"*"&"精简"&"*")>0,1,0) -> 0 | AJ7: =MIN(1,AA7*($AY$2+IF(AND(AB7>=$AQ$3,AC7>=$AR$3,AD7>=$AS$3,AE7>=$AT$3,AF7>=$AU$3,AG7>=$AV$3,AH7>=$AW$3,AI7>=$AX$3),1,0))) -> 1 | AK7: =SUM(AJ$2:$AJ7) -> 6
A8: 暗器 | B8: 6_40933 | C8: 润源囊 | D8: 30200 | E8: 润源囊(30200速无) | F8: 9948 | G8: 812 | I8: 1843 | J8: 0 | K8: 0 | L8: 0 | M8: 0 | N8: 5426 | O8: 6783 | P8: 0 | R8: 0 | S8: 0 | T8: 速无 | U8: 6 | V8: 副本 | W8: 身法孔 | Z8: 1 | AA8: =IF(AND(D8>=配装计算器!$I$29,D8<=配装计算器!$I$30),1,0) -> 1 | AB8: =IF(J8>0,1,0) -> 0 | AC8: =IF(K8>0,1,0) -> 0 | AD8: =IF(L8>0,1,0) -> 0 | AE8: =IF(M8>0,1,0) -> 0 | AF8: =IF(N8>0,1,0) -> 1 | AG8: =IF(O8>0,1,0) -> 1 | AH8: =IF(P8>0,1,0) -> 0 | AI8: =IF(COUNTIF(T8,"*"&"精简"&"*")>0,1,0) -> 0 | AJ8: =MIN(1,AA8*($AY$2+IF(AND(AB8>=$AQ$3,AC8>=$AR$3,AD8>=$AS$3,AE8>=$AT$3,AF8>=$AU$3,AG8>=$AV$3,AH8>=$AW$3,AI8>=$AX$3),1,0))) -> 1 | AK8: =SUM(AJ$2:$AJ8) -> 7
A9: 暗器 | B9: 6_41180 | C9: 问殿囊 | D9: 30200 | E9: 问殿囊(30200速无) | F9: 9948 | G9: 812 | I9: 1843 | J9: 0 | K9: 0 | L9: 0 | M9: 0 | N9: 5426 | O9: 6783 | P9: 0 | R9: 0 | S9: 0 | T9: 速无 | U9: 6 | V9: 副本 | W9: 身法孔 | Z9: 1 | AA9: =IF(AND(D9>=配装计算器!$I$29,D9<=配装计算器!$I$30),1,0) -> 1 | AB9: =IF(J9>0,1,0) -> 0 | AC9: =IF(K9>0,1,0) -> 0 | AD9: =IF(L9>0,1,0) -> 0 | AE9: =IF(M9>0,1,0) -> 0 | AF9: =IF(N9>0,1,0) -> 1 | AG9: =IF(O9>0,1,0) -> 1 | AH9: =IF(P9>0,1,0) -> 0 | AI9: =IF(COUNTIF(T9,"*"&"精简"&"*")>0,1,0) -> 0 | AJ9: =MIN(1,AA9*($AY$2+IF(AND(AB9>=$AQ$3,AC9>=$AR$3,AD9>=$AS$3,AE9>=$AT$3,AF9>=$AU$3,AG9>=$AV$3,AH9>=$AW$3,AI9>=$AX$3),1,0))) -> 1 | AK9: =SUM(AJ$2:$AJ9) -> 8
A10: 暗器 | B10: 6_40918 | C10: 平皋囊 | D10: 30200 | E10: 平皋囊(30200破无) | F10: 9948 | G10: 812 | I10: 1843 | J10: 0 | K10: 0 | L10: 6783 | M10: 0 | N10: 5426 | O10: 0 | P10: 0 | R10: 0 | S10: 0 | T10: 破无 | U10: 6 | V10: 副本 | W10: 攻击孔 | Z10: 1 | AA10: =IF(AND(D10>=配装计算器!$I$29,D10<=配装计算器!$I$30),1,0) -> 1 | AB10: =IF(J10>0,1,0) -> 0 | AC10: =IF(K10>0,1,0) -> 0 | AD10: =IF(L10>0,1,0) -> 1 | AE10: =IF(M10>0,1,0) -> 0 | AF10: =IF(N10>0,1,0) -> 1 | AG10: =IF(O10>0,1,0) -> 0 | AH10: =IF(P10>0,1,0) -> 0 | AI10: =IF(COUNTIF(T10,"*"&"精简"&"*")>0,1,0) -> 0 | AJ10: =MIN(1,AA10*($AY$2+IF(AND(AB10>=$AQ$3,AC10>=$AR$3,AD10>=$AS$3,AE10>=$AT$3,AF10>=$AU$3,AG10>=$AV$3,AH10>=$AW$3,AI10>=$AX$3),1,0))) -> 1 | AK10: =SUM(AJ$2:$AJ10) -> 9
A11: 暗器 | B11: 6_41220 | C11: 标雁囊 | D11: 30200 | E11: 标雁囊(30200会无) | F11: 9948 | G11: 812 | I11: 1843 | J11: 6783 | K11: 0 | L11: 0 | M11: 0 | N11: 5426 | O11: 0 | P11: 0 | R11: 0 | S11: 0 | T11: 会无 | U11: 6 | V11: 副本 | W11: 会心孔 | Z11: 1 | AA11: =IF(AND(D11>=配装计算器!$I$29,D11<=配装计算器!$I$30),1,0) -> 1 | AB11: =IF(J11>0,1,0) -> 1 | AC11: =IF(K11>0,1,0) -> 0 | AD11: =IF(L11>0,1,0) -> 0 | AE11: =IF(M11>0,1,0) -> 0 | AF11: =IF(N11>0,1,0) -> 1 | AG11: =IF(O11>0,1,0) -> 0 | AH11: =IF(P11>0,1,0) -> 0 | AI11: =IF(COUNTIF(T11,"*"&"精简"&"*")>0,1,0) -> 0 | AJ11: =MIN(1,AA11*($AY$2+IF(AND(AB11>=$AQ$3,AC11>=$AR$3,AD11>=$AS$3,AE11>=$AT$3,AF11>=$AU$3,AG11>=$AV$3,AH11>=$AW$3,AI11>=$AX$3),1,0))) -> 1 | AK11: =SUM(AJ$2:$AJ11) -> 10
A12: 暗器 | B12: 6_41354 | C12: 坠红囊 | D12: 30200 | E12: 坠红囊(30200会无) | F12: 9948 | G12: 812 | I12: 1843 | J12: 6783 | K12: 0 | L12: 0 | M12: 0 | N12: 5426 | O12: 0 | P12: 0 | R12: 0 | S12: 0 | T12: 会无 | U12: 6 | V12: 世界BOSS | W12: 会心孔 | Z12: 1 | AA12: =IF(AND(D12>=配装计算器!$I$29,D12<=配装计算器!$I$30),1,0) -> 1 | AB12: =IF(J12>0,1,0) -> 1 | AC12: =IF(K12>0,1,0) -> 0 | AD12: =IF(L12>0,1,0) -> 0 | AE12: =IF(M12>0,1,0) -> 0 | AF12: =IF(N12>0,1,0) -> 1 | AG12: =IF(O12>0,1,0) -> 0 | AH12: =IF(P12>0,1,0) -> 0 | AI12: =IF(COUNTIF(T12,"*"&"精简"&"*")>0,1,0) -> 0 | AJ12: =MIN(1,AA12*($AY$2+IF(AND(AB12>=$AQ$3,AC12>=$AR$3,AD12>=$AS$3,AE12>=$AT$3,AF12>=$AU$3,AG12>=$AV$3,AH12>=$AW$3,AI12>=$AX$3),1,0))) -> 1 | AK12: =SUM(AJ$2:$AJ12) -> 11
A13: 暗器 | B13: 6_41348 | C13: 无修囊·外·玄 | D13: 30200 | E13: 无修囊·外·玄(30200特效精简无) | F13: 9948 | G13: 0 | I13: 4178 | J13: 0 | K13: 0 | L13: 0 | M13: 0 | N13: 9948 | O13: 0 | P13: 0 | R13: 0 | S13: 0 | T13: 特效精简无 | U13: 6 | V13: 活动 | W13: 破防孔 | Z13: 1 | AA13: =IF(AND(D13>=配装计算器!$I$29,D13<=配装计算器!$I$30),1,0) -> 1 | AB13: =IF(J13>0,1,0) -> 0 | AC13: =IF(K13>0,1,0) -> 0 | AD13: =IF(L13>0,1,0) -> 0 | AE13: =IF(M13>0,1,0) -> 0 | AF13: =IF(N13>0,1,0) -> 1 | AG13: =IF(O13>0,1,0) -> 0 | AH13: =IF(P13>0,1,0) -> 0 | AI13: =IF(COUNTIF(T13,"*"&"精简"&"*")>0,1,0) -> 1 | AJ13: =MIN(1,AA13*($AY$2+IF(AND(AB13>=$AQ$3,AC13>=$AR$3,AD13>=$AS$3,AE13>=$AT$3,AF13>=$AU$3,AG13>=$AV$3,AH13>=$AW$3,AI13>=$AX$3),1,0))) -> 1 | AK13: =SUM(AJ$2:$AJ13) -> 12
A14: 暗器 | B14: 6_41349 | C14: 无修囊·外·玄 | D14: 30200 | E14: 无修囊·外·玄(30200特效精简会招无) | F14: 9948 | G14: 0 | I14: 3564 | J14: 4522 | K14: 0 | L14: 0 | M14: 4522 | N14: 4522 | O14: 0 | P14: 0 | R14: 0 | S14: 0 | T14: 特效精简会招无 | U14: 6 | V14: 活动 | W14: 破防孔 | Z14: 1 | AA14: =IF(AND(D14>=配装计算器!$I$29,D14<=配装计算器!$I$30),1,0) -> 1 | AB14: =IF(J14>0,1,0) -> 1 | AC14: =IF(K14>0,1,0) -> 0 | AD14: =IF(L14>0,1,0) -> 0 | AE14: =IF(M14>0,1,0) -> 1 | AF14: =IF(N14>0,1,0) -> 1 | AG14: =IF(O14>0,1,0) -> 0 | AH14: =IF(P14>0,1,0) -> 0 | AI14: =IF(COUNTIF(T14,"*"&"精简"&"*")>0,1,0) -> 1 | AJ14: =MIN(1,AA14*($AY$2+IF(AND(AB14>=$AQ$3,AC14>=$AR$3,AD14>=$AS$3,AE14>=$AT$3,AF14>=$AU$3,AG14>=$AV$3,AH14>=$AW$3,AI14>=$AX$3),1,0))) -> 1 | AK14: =SUM(AJ$2:$AJ14) -> 13
A15: 暗器 | B15: 6_41350 | C15: 无修囊·外·玄 | D15: 30200 | E15: 无修囊·外·玄(30200特效精简会会无) | F15: 9948 | G15: 0 | I15: 3564 | J15: 6783 | K15: 3391 | L15: 0 | M15: 0 | N15: 3391 | O15: 0 | P15: 0 | R15: 0 | S15: 0 | T15: 特效精简会会无 | U15: 6 | V15: 活动 | W15: 破防孔 | Z15: 1 | AA15: =IF(AND(D15>=配装计算器!$I$29,D15<=配装计算器!$I$30),1,0) -> 1 | AB15: =IF(J15>0,1,0) -> 1 | AC15: =IF(K15>0,1,0) -> 1 | AD15: =IF(L15>0,1,0) -> 0 | AE15: =IF(M15>0,1,0) -> 0 | AF15: =IF(N15>0,1,0) -> 1 | AG15: =IF(O15>0,1,0) -> 0 | AH15: =IF(P15>0,1,0) -> 0 | AI15: =IF(COUNTIF(T15,"*"&"精简"&"*")>0,1,0) -> 1 | AJ15: =MIN(1,AA15*($AY$2+IF(AND(AB15>=$AQ$3,AC15>=$AR$3,AD15>=$AS$3,AE15>=$AT$3,AF15>=$AU$3,AG15>=$AV$3,AH15>=$AW$3,AI15>=$AX$3),1,0))) -> 1 | AK15: =SUM(AJ$2:$AJ15) -> 14
... A42: 暗器 | B42: 6_45223 | C42: 陶然意·烟峦囊 | D42: 42400 | E42: 陶然意·烟峦囊(42400破全) | F42: 15236 | G42: 1058 | I42: 2588 | J42: 0 | K42: 0 | L42: 9523 | M42: 0 | N42: 0 | O42: 0 | P42: 635 | R42: 0 | S42: 0 | T42: 破全 | U42: 6 | V42: PVX | W42: 身法孔 | Z42: 2 | AA42: =IF(AND(D42>=配装计算器!$I$29,D42<=配装计算器!$I$30),1,0) -> 1 | AB42: =IF(J42>0,1,0) -> 0 | AC42: =IF(K42>0,1,0) -> 0 | AD42: =IF(L42>0,1,0) -> 1 | AE42: =IF(M42>0,1,0) -> 0 | AF42: =IF(N42>0,1,0) -> 0 | AG42: =IF(O42>0,1,0) -> 0 | AH42: =IF(P42>0,1,0) -> 1 | AI42: =IF(COUNTIF(T42,"*"&"精简"&"*")>0,1,0) -> 0 | AJ42: =MIN(1,AA42*($AY$2+IF(AND(AB42>=$AQ$3,AC42>=$AR$3,AD42>=$AS$3,AE42>=$AT$3,AF42>=$AU$3,AG42>=$AV$3,AH42>=$AW$3,AI42>=$AX$3),1,0))) -> 1 | AK42: =SUM(AJ$2:$AJ42) -> 41
A43: 护手 | B43: 7_108485 | C43: 智渊袖 | D43: 30200 | E43: 智渊袖(30200速全) | F43: 11606 | G43: 879 | I43: 1434 | J43: 0 | K43: 0 | L43: 0 | M43: 0 | N43: 0 | O43: 7913 | P43: 3165 | R43: 0 | S43: 0 | T43: 速全 | U43: 6 | V43: 副本 | W43: 最大气血值 | X43: 身法孔 | Z43: 2 | AA43: =IF(AND(D43>=配装计算器!$I$29,D43<=配装计算器!$I$30),1,0) -> 1 | AB43: =IF(J43>0,1,0) -> 0 | AC43: =IF(K43>0,1,0) -> 0 | AD43: =IF(L43>0,1,0) -> 0 | AE43: =IF(M43>0,1,0) -> 0 | AF43: =IF(N43>0,1,0) -> 0 | AG43: =IF(O43>0,1,0) -> 1 | AH43: =IF(P43>0,1,0) -> 1 | AI43: =IF(COUNTIF(T43,"*"&"精简"&"*")>0,1,0) -> 0 | AJ43: =MIN(1,AA43*($AY$2+IF(AND(AB43>=$AQ$3,AC43>=$AR$3,AD43>=$AS$3,AE43>=$AT$3,AF43>=$AU$3,AG43>=$AV$3,AH43>=$AW$3,AI43>=$AX$3),1,0))) -> 1 | AK43: =SUM(AJ$2:$AJ43) -> 42
A44: 护手 | B44: 7_108521 | C44: 镂云袖 | D44: 30200 | E44: 镂云袖(30200会全) | F44: 11606 | G44: 879 | I44: 1434 | J44: 7913 | K44: 0 | L44: 0 | M44: 0 | N44: 0 | O44: 0 | P44: 3165 | R44: 0 | S44: 0 | T44: 会全 | U44: 6 | V44: 副本 | W44: 身法孔 | X44: 全能孔 | Z44: 2 | AA44: =IF(AND(D44>=配装计算器!$I$29,D44<=配装计算器!$I$30),1,0) -> 1 | AB44: =IF(J44>0,1,0) -> 1 | AC44: =IF(K44>0,1,0) -> 0 | AD44: =IF(L44>0,1,0) -> 0 | AE44: =IF(M44>0,1,0) -> 0 | AF44: =IF(N44>0,1,0) -> 0 | AG44: =IF(O44>0,1,0) -> 0 | AH44: =IF(P44>0,1,0) -> 1 | AI44: =IF(COUNTIF(T44,"*"&"精简"&"*")>0,1,0) -> 0 | AJ44: =MIN(1,AA44*($AY$2+IF(AND(AB44>=$AQ$3,AC44>=$AR$3,AD44>=$AS$3,AE44>=$AT$3,AF44>=$AU$3,AG44>=$AV$3,AH44>=$AW$3,AI44>=$AX$3),1,0))) -> 1 | AK44: =SUM(AJ$2:$AJ44) -> 43
A45: 护手 | B45: 7_110982 | C45: 臻泽袖 | D45: 30200 | E45: 臻泽袖(30200会全) | F45: 11606 | G45: 879 | I45: 1434 | J45: 7913 | K45: 0 | L45: 0 | M45: 0 | N45: 0 | O45: 0 | P45: 3165 | R45: 0 | S45: 0 | T45: 会全 | U45: 6 | V45: 活动 | W45: 身法孔 | X45: 全能孔 | Z45: 2 | AA45: =IF(AND(D45>=配装计算器!$I$29,D45<=配装计算器!$I$30),1,0) -> 1 | AB45: =IF(J45>0,1,0) -> 1 | AC45: =IF(K45>0,1,0) -> 0 | AD45: =IF(L45>0,1,0) -> 0 | AE45: =IF(M45>0,1,0) -> 0 | AF45: =IF(N45>0,1,0) -> 0 | AG45: =IF(O45>0,1,0) -> 0 | AH45: =IF(P45>0,1,0) -> 1 | AI45: =IF(COUNTIF(T45,"*"&"精简"&"*")>0,1,0) -> 0 | AJ45: =MIN(1,AA45*($AY$2+IF(AND(AB45>=$AQ$3,AC45>=$AR$3,AD45>=$AS$3,AE45>=$AT$3,AF45>=$AU$3,AG45>=$AV$3,AH45>=$AW$3,AI45>=$AX$3),1,0))) -> 1 | AK45: =SUM(AJ$2:$AJ45) -> 44
A46: 护手 | B46: 7_104665 | C46: 【门派套装】天极·听荷护手 | D46: 30200 | E46: 【门派套装】天极·听荷护手(30200招无) | F46: 11606 | G46: 947 | I46: 2150 | J46: 0 | K46: 0 | L46: 0 | M46: 7913 | N46: 6330 | O46: 0 | P46: 0 | R46: 0 | S46: 0 | T46: 招无 | U46: 6 | V46: 兑换牌 | W46: 破防孔 | X46: 破招孔 | Z46: 1 | AA46: =IF(AND(D46>=配装计算器!$I$29,D46<=配装计算器!$I$30),1,0) -> 1 | AB46: =IF(J46>0,1,0) -> 0 | AC46: =IF(K46>0,1,0) -> 0 | AD46: =IF(L46>0,1,0) -> 0 | AE46: =IF(M46>0,1,0) -> 1 | AF46: =IF(N46>0,1,0) -> 1 | AG46: =IF(O46>0,1,0) -> 0 | AH46: =IF(P46>0,1,0) -> 0 | AI46: =IF(COUNTIF(T46,"*"&"精简"&"*")>0,1,0) -> 0 | AJ46: =MIN(1,AA46*($AY$2+IF(AND(AB46>=$AQ$3,AC46>=$AR$3,AD46>=$AS$3,AE46>=$AT$3,AF46>=$AU$3,AG46>=$AV$3,AH46>=$AW$3,AI46>=$AX$3),1,0))) -> 1 | AK46: =SUM(AJ$2:$AJ46) -> 45
A47: 护手 | B47: 7_108221 | C47: 孤城惊梦·迷烟护腕 | D47: 30200 | E47: 孤城惊梦·迷烟护腕(30200招无) | F47: 11606 | G47: 947 | I47: 2150 | J47: 0 | K47: 0 | L47: 0 | M47: 7913 | N47: 6330 | O47: 0 | P47: 0 | R47: 0 | S47: 0 | T47: 招无 | U47: 6 | V47: 飞沙令 | W47: 破防孔 | X47: 破招孔 | Z47: 1 | AA47: =IF(AND(D47>=配装计算器!$I$29,D47<=配装计算器!$I$30),1,0) -> 1 | AB47: =IF(J47>0,1,0) -> 0 | AC47: =IF(K47>0,1,0) -> 0 | AD47: =IF(L47>0,1,0) -> 0 | AE47: =IF(M47>0,1,0) -> 1 | AF47: =IF(N47>0,1,0) -> 1 | AG47: =IF(O47>0,1,0) -> 0 | AH47: =IF(P47>0,1,0) -> 0 | AI47: =IF(COUNTIF(T47,"*"&"精简"&"*")>0,1,0) -> 0 | AJ47: =MIN(1,AA47*($AY$2+IF(AND(AB47>=$AQ$3,AC47>=$AR$3,AD47>=$AS$3,AE47>=$AT$3,AF47>=$AU$3,AG47>=$AV$3,AH47>=$AW$3,AI47>=$AX$3),1,0))) -> 1 | AK47: =SUM(AJ$2:$AJ47) -> 46
A48: 护手 | B48: 7_104503 | C48: 润源袖 | D48: 30200 | E48: 润源袖(30200招无) | F48: 11606 | G48: 947 | I48: 2150 | J48: 0 | K48: 0 | L48: 0 | M48: 7913 | N48: 6330 | O48: 0 | P48: 0 | R48: 0 | S48: 0 | T48: 招无 | U48: 6 | V48: 副本 | W48: 破防孔 | X48: 破招孔 | Z48: 1 | AA48: =IF(AND(D48>=配装计算器!$I$29,D48<=配装计算器!$I$30),1,0) -> 1 | AB48: =IF(J48>0,1,0) -> 0 | AC48: =IF(K48>0,1,0) -> 0 | AD48: =IF(L48>0,1,0) -> 0 | AE48: =IF(M48>0,1,0) -> 1 | AF48: =IF(N48>0,1,0) -> 1 | AG48: =IF(O48>0,1,0) -> 0 | AH48: =IF(P48>0,1,0) -> 0 | AI48: =IF(COUNTIF(T48,"*"&"精简"&"*")>0,1,0) -> 0 | AJ48: =MIN(1,AA48*($AY$2+IF(AND(AB48>=$AQ$3,AC48>=$AR$3,AD48>=$AS$3,AE48>=$AT$3,AF48>=$AU$3,AG48>=$AV$3,AH48>=$AW$3,AI48>=$AX$3),1,0))) -> 1 | AK48: =SUM(AJ$2:$AJ48) -> 47
A49: 护手 | B49: 7_104457 | C49: 羽缀护手 | D49: 30200 | E49: 羽缀护手(30200速无) | F49: 11606 | G49: 947 | I49: 2150 | J49: 0 | K49: 0 | L49: 0 | M49: 0 | N49: 6330 | O49: 7913 | P49: 0 | R49: 0 | S49: 0 | T49: 速无 | U49: 6 | V49: 副本 | W49: 破防孔 | X49: 身法孔 | Z49: 1 | AA49: =IF(AND(D49>=配装计算器!$I$29,D49<=配装计算器!$I$30),1,0) -> 1 | AB49: =IF(J49>0,1,0) -> 0 | AC49: =IF(K49>0,1,0) -> 0 | AD49: =IF(L49>0,1,0) -> 0 | AE49: =IF(M49>0,1,0) -> 0 | AF49: =IF(N49>0,1,0) -> 1 | AG49: =IF(O49>0,1,0) -> 1 | AH49: =IF(P49>0,1,0) -> 0 | AI49: =IF(COUNTIF(T49,"*"&"精简"&"*")>0,1,0) -> 0 | AJ49: =MIN(1,AA49*($AY$2+IF(AND(AB49>=$AQ$3,AC49>=$AR$3,AD49>=$AS$3,AE49>=$AT$3,AF49>=$AU$3,AG49>=$AV$3,AH49>=$AW$3,AI49>=$AX$3),1,0))) -> 1 | AK49: =SUM(AJ$2:$AJ49) -> 48
A50: 护手 | B50: 7_104809 | C50: 问殿护手 | D50: 30200 | E50: 问殿护手(30200速无) | F50: 11606 | G50: 947 | I50: 2150 | J50: 0 | K50: 0 | L50: 0 | M50: 0 | N50: 6330 | O50: 7913 | P50: 0 | R50: 0 | S50: 0 | T50: 速无 | U50: 6 | V50: 副本 | W50: 破防孔 | X50: 身法孔 | Z50: 1 | AA50: =IF(AND(D50>=配装计算器!$I$29,D50<=配装计算器!$I$30),1,0) -> 1 | AB50: =IF(J50>0,1,0) -> 0 | AC50: =IF(K50>0,1,0) -> 0 | AD50: =IF(L50>0,1,0) -> 0 | AE50: =IF(M50>0,1,0) -> 0 | AF50: =IF(N50>0,1,0) -> 1 | AG50: =IF(O50>0,1,0) -> 1 | AH50: =IF(P50>0,1,0) -> 0 | AI50: =IF(COUNTIF(T50,"*"&"精简"&"*")>0,1,0) -> 0 | AJ50: =MIN(1,AA50*($AY$2+IF(AND(AB50>=$AQ$3,AC50>=$AR$3,AD50>=$AS$3,AE50>=$AT$3,AF50>=$AU$3,AG50>=$AV$3,AH50>=$AW$3,AI50>=$AX$3),1,0))) -> 1 | AK50: =SUM(AJ$2:$AJ50) -> 49
A51: 护手 | B51: 7_104114 | C51: 平皋袖 | D51: 30200 | E51: 平皋袖(30200破无) | F51: 11606 | G51: 947 | I51: 2150 | J51: 0 | K51: 0 | L51: 7913 | M51: 0 | N51: 6330 | O51: 0 | P51: 0 | R51: 0 | S51: 0 | T51: 破无 | U51: 6 | V51: 副本 | W51: 无双孔 | X51: 身法孔 | Z51: 1 | AA51: =IF(AND(D51>=配装计算器!$I$29,D51<=配装计算器!$I$30),1,0) -> 1 | AB51: =IF(J51>0,1,0) -> 0 | AC51: =IF(K51>0,1,0) -> 0 | AD51: =IF(L51>0,1,0) -> 1 | AE51: =IF(M51>0,1,0) -> 0 | AF51: =IF(N51>0,1,0) -> 1 | AG51: =IF(O51>0,1,0) -> 0 | AH51: =IF(P51>0,1,0) -> 0 | AI51: =IF(COUNTIF(T51,"*"&"精简"&"*")>0,1,0) -> 0 | AJ51: =MIN(1,AA51*($AY$2+IF(AND(AB51>=$AQ$3,AC51>=$AR$3,AD51>=$AS$3,AE51>=$AT$3,AF51>=$AU$3,AG51>=$AV$3,AH51>=$AW$3,AI51>=$AX$3),1,0))) -> 1 | AK51: =SUM(AJ$2:$AJ51) -> 50
A52: 护手 | B52: 7_104845 | C52: 标雁护手 | D52: 30200 | E52: 标雁护手(30200破无) | F52: 11606 | G52: 947 | I52: 2150 | J52: 0 | K52: 0 | L52: 7913 | M52: 0 | N52: 6330 | O52: 0 | P52: 0 | R52: 0 | S52: 0 | T52: 破无 | U52: 6 | V52: 副本 | W52: 无双孔 | X52: 身法孔 | Z52: 1 | AA52: =IF(AND(D52>=配装计算器!$I$29,D52<=配装计算器!$I$30),1,0) -> 1 | AB52: =IF(J52>0,1,0) -> 0 | AC52: =IF(K52>0,1,0) -> 0 | AD52: =IF(L52>0,1,0) -> 1 | AE52: =IF(M52>0,1,0) -> 0 | AF52: =IF(N52>0,1,0) -> 1 | AG52: =IF(O52>0,1,0) -> 0 | AH52: =IF(P52>0,1,0) -> 0 | AI52: =IF(COUNTIF(T52,"*"&"精简"&"*")>0,1,0) -> 0 | AJ52: =MIN(1,AA52*($AY$2+IF(AND(AB52>=$AQ$3,AC52>=$AR$3,AD52>=$AS$3,AE52>=$AT$3,AF52>=$AU$3,AG52>=$AV$3,AH52>=$AW$3,AI52>=$AX$3),1,0))) -> 1 | AK52: =SUM(AJ$2:$AJ52) -> 51
A53: 护手 | B53: 7_105007 | C53: 客行江湖·日斜袖 | D53: 30200 | E53: 客行江湖·日斜袖(30200会无) | F53: 11606 | G53: 947 | I53: 2150 | J53: 7913 | K53: 0 | L53: 0 | M53: 0 | N53: 6330 | O53: 0 | P53: 0 | R53: 0 | S53: 0 | T53: 会无 | U53: 6 | V53: 浪客笺 | W53: 会心孔 | X53: 攻击孔 | Z53: 1 | AA53: =IF(AND(D53>=配装计算器!$I$29,D53<=配装计算器!$I$30),1,0) -> 1 | AB53: =IF(J53>0,1,0) -> 1 | AC53: =IF(K53>0,1,0) -> 0 | AD53: =IF(L53>0,1,0) -> 0 | AE53: =IF(M53>0,1,0) -> 0 | AF53: =IF(N53>0,1,0) -> 1 | AG53: =IF(O53>0,1,0) -> 0 | AH53: =IF(P53>0,1,0) -> 0 | AI53: =IF(COUNTIF(T53,"*"&"精简"&"*")>0,1,0) -> 0 | AJ53: =MIN(1,AA53*($AY$2+IF(AND(AB53>=$AQ$3,AC53>=$AR$3,AD53>=$AS$3,AE53>=$AT$3,AF53>=$AU$3,AG53>=$AV$3,AH53>=$AW$3,AI53>=$AX$3),1,0))) -> 1 | AK53: =SUM(AJ$2:$AJ53) -> 52
A54: 护手 | B54: 7_105073 | C54: 坠红袖 | D54: 30200 | E54: 坠红袖(30200会无) | F54: 11606 | G54: 947 | I54: 2150 | J54: 7913 | K54: 0 | L54: 0 | M54: 0 | N54: 6330 | O54: 0 | P54: 0 | R54: 0 | S54: 0 | T54: 会无 | U54: 6 | V54: 世界BOSS | W54: 会心孔 | X54: 攻击孔 | Z54: 1 | AA54: =IF(AND(D54>=配装计算器!$I$29,D54<=配装计算器!$I$30),1,0) -> 1 | AB54: =IF(J54>0,1,0) -> 1 | AC54: =IF(K54>0,1,0) -> 0 | AD54: =IF(L54>0,1,0) -> 0 | AE54: =IF(M54>0,1,0) -> 0 | AF54: =IF(N54>0,1,0) -> 1 | AG54: =IF(O54>0,1,0) -> 0 | AH54: =IF(P54>0,1,0) -> 0 | AI54: =IF(COUNTIF(T54,"*"&"精简"&"*")>0,1,0) -> 0 | AJ54: =MIN(1,AA54*($AY$2+IF(AND(AB54>=$AQ$3,AC54>=$AR$3,AD54>=$AS$3,AE54>=$AT$3,AF54>=$AU$3,AG54>=$AV$3,AH54>=$AW$3,AI54>=$AX$3),1,0))) -> 1 | AK54: =SUM(AJ$2:$AJ54) -> 53
... A117: 护手 | B117: 7_110787 | C117: 陶然意·烟峦护手 | D117: 42400 | E117: 陶然意·烟峦护手(42400破全) | F117: 16294 | G117: 1234 | I117: 2013 | J117: 0 | K117: 0 | L117: 11110 | M117: 0 | N117: 0 | O117: 0 | P117: 4444 | R117: 0 | S117: 0 | T117: 破全 | U117: 6 | V117: PVX | W117: 最大气血值 | X117: 破防孔 | Z117: 2 | AA117: =IF(AND(D117>=配装计算器!$I$29,D117<=配装计算器!$I$30),1,0) -> 1 | AB117: =IF(J117>0,1,0) -> 0 | AC117: =IF(K117>0,1,0) -> 0 | AD117: =IF(L117>0,1,0) -> 1 | AE117: =IF(M117>0,1,0) -> 0 | AF117: =IF(N117>0,1,0) -> 0 | AG117: =IF(O117>0,1,0) -> 0 | AH117: =IF(P117>0,1,0) -> 1 | AI117: =IF(COUNTIF(T117,"*"&"精简"&"*")>0,1,0) -> 0 | AJ117: =MIN(1,AA117*($AY$2+IF(AND(AB117>=$AQ$3,AC117>=$AR$3,AD117>=$AS$3,AE117>=$AT$3,AF117>=$AU$3,AG117>=$AV$3,AH117>=$AW$3,AI117>=$AX$3),1,0))) -> 1 | AK117: =SUM(AJ$2:$AJ117) -> 116
A118: 戒指 | B118: 8_45509 | C118: 镂云戒 | D118: 30200 | E118: 镂云戒(30200速全) | F118: 8290 | G118: 628 | I118: 1024 | J118: 0 | K118: 0 | L118: 0 | M118: 0 | N118: 0 | O118: 5652 | P118: 2261 | R118: 0 | S118: 0 | T118: 速全 | U118: 6 | V118: 副本 | Z118: 2 | AA118: =IF(AND(D118>=配装计算器!$I$29,D118<=配装计算器!$I$30),1,0) -> 1 | AB118: =IF(J118>0,1,0) -> 0 | AC118: =IF(K118>0,1,0) -> 0 | AD118: =IF(L118>0,1,0) -> 0 | AE118: =IF(M118>0,1,0) -> 0 | AF118: =IF(N118>0,1,0) -> 0 | AG118: =IF(O118>0,1,0) -> 1 | AH118: =IF(P118>0,1,0) -> 1 | AI118: =IF(COUNTIF(T118,"*"&"精简"&"*")>0,1,0) -> 0 | AJ118: =MIN(1,AA118*($AY$2+IF(AND(AB118>=$AQ$3,AC118>=$AR$3,AD118>=$AS$3,AE118>=$AT$3,AF118>=$AU$3,AG118>=$AV$3,AH118>=$AW$3,AI118>=$AX$3),1,0))) -> 1 | AK118: =SUM(AJ$2:$AJ118) -> 117
A119: 戒指 | B119: 8_45491 | C119: 智渊戒 | D119: 30200 | E119: 智渊戒(30200破全) | F119: 8290 | G119: 628 | I119: 1024 | J119: 0 | K119: 0 | L119: 5652 | M119: 0 | N119: 0 | O119: 0 | P119: 2261 | R119: 0 | S119: 0 | T119: 破全 | U119: 6 | V119: 副本 | Z119: 2 | AA119: =IF(AND(D119>=配装计算器!$I$29,D119<=配装计算器!$I$30),1,0) -> 1 | AB119: =IF(J119>0,1,0) -> 0 | AC119: =IF(K119>0,1,0) -> 0 | AD119: =IF(L119>0,1,0) -> 1 | AE119: =IF(M119>0,1,0) -> 0 | AF119: =IF(N119>0,1,0) -> 0 | AG119: =IF(O119>0,1,0) -> 0 | AH119: =IF(P119>0,1,0) -> 1 | AI119: =IF(COUNTIF(T119,"*"&"精简"&"*")>0,1,0) -> 0 | AJ119: =MIN(1,AA119*($AY$2+IF(AND(AB119>=$AQ$3,AC119>=$AR$3,AD119>=$AS$3,AE119>=$AT$3,AF119>=$AU$3,AG119>=$AV$3,AH119>=$AW$3,AI119>=$AX$3),1,0))) -> 1 | AK119: =SUM(AJ$2:$AJ119) -> 118
A120: 戒指 | B120: 8_49355 | C120: 臻泽戒 | D120: 30200 | E120: 臻泽戒(30200会全) | F120: 8290 | G120: 628 | I120: 1024 | J120: 5652 | K120: 0 | L120: 0 | M120: 0 | N120: 0 | O120: 0 | P120: 2261 | R120: 0 | S120: 0 | T120: 会全 | U120: 6 | V120: 活动 | Z120: 2 | AA120: =IF(AND(D120>=配装计算器!$I$29,D120<=配装计算器!$I$30),1,0) -> 1 | AB120: =IF(J120>0,1,0) -> 1 | AC120: =IF(K120>0,1,0) -> 0 | AD120: =IF(L120>0,1,0) -> 0 | AE120: =IF(M120>0,1,0) -> 0 | AF120: =IF(N120>0,1,0) -> 0 | AG120: =IF(O120>0,1,0) -> 0 | AH120: =IF(P120>0,1,0) -> 1 | AI120: =IF(COUNTIF(T120,"*"&"精简"&"*")>0,1,0) -> 0 | AJ120: =MIN(1,AA120*($AY$2+IF(AND(AB120>=$AQ$3,AC120>=$AR$3,AD120>=$AS$3,AE120>=$AT$3,AF120>=$AU$3,AG120>=$AV$3,AH120>=$AW$3,AI120>=$AX$3),1,0))) -> 1 | AK120: =SUM(AJ$2:$AJ120) -> 119
A121: 戒指 | B121: 8_42860 | C121: 羽缀戒 | D121: 30200 | E121: 羽缀戒(30200招无) | F121: 8290 | G121: 676 | I121: 1536 | J121: 0 | K121: 0 | L121: 0 | M121: 5652 | N121: 4522 | O121: 0 | P121: 0 | R121: 0 | S121: 0 | T121: 招无 | U121: 6 | V121: 副本 | Z121: 1 | AA121: =IF(AND(D121>=配装计算器!$I$29,D121<=配装计算器!$I$30),1,0) -> 1 | AB121: =IF(J121>0,1,0) -> 0 | AC121: =IF(K121>0,1,0) -> 0 | AD121: =IF(L121>0,1,0) -> 0 | AE121: =IF(M121>0,1,0) -> 1 | AF121: =IF(N121>0,1,0) -> 1 | AG121: =IF(O121>0,1,0) -> 0 | AH121: =IF(P121>0,1,0) -> 0 | AI121: =IF(COUNTIF(T121,"*"&"精简"&"*")>0,1,0) -> 0 | AJ121: =MIN(1,AA121*($AY$2+IF(AND(AB121>=$AQ$3,AC121>=$AR$3,AD121>=$AS$3,AE121>=$AT$3,AF121>=$AU$3,AG121>=$AV$3,AH121>=$AW$3,AI121>=$AX$3),1,0))) -> 1 | AK121: =SUM(AJ$2:$AJ121) -> 120
A122: 戒指 | B122: 8_42954 | C122: 问殿指环 | D122: 30200 | E122: 问殿指环(30200招无) | F122: 8290 | G122: 676 | I122: 1536 | J122: 0 | K122: 0 | L122: 0 | M122: 5652 | N122: 4522 | O122: 0 | P122: 0 | R122: 0 | S122: 0 | T122: 招无 | U122: 6 | V122: 副本 | Z122: 1 | AA122: =IF(AND(D122>=配装计算器!$I$29,D122<=配装计算器!$I$30),1,0) -> 1 | AB122: =IF(J122>0,1,0) -> 0 | AC122: =IF(K122>0,1,0) -> 0 | AD122: =IF(L122>0,1,0) -> 0 | AE122: =IF(M122>0,1,0) -> 1 | AF122: =IF(N122>0,1,0) -> 1 | AG122: =IF(O122>0,1,0) -> 0 | AH122: =IF(P122>0,1,0) -> 0 | AI122: =IF(COUNTIF(T122,"*"&"精简"&"*")>0,1,0) -> 0 | AJ122: =MIN(1,AA122*($AY$2+IF(AND(AB122>=$AQ$3,AC122>=$AR$3,AD122>=$AS$3,AE122>=$AT$3,AF122>=$AU$3,AG122>=$AV$3,AH122>=$AW$3,AI122>=$AX$3),1,0))) -> 1 | AK122: =SUM(AJ$2:$AJ122) -> 121
A123: 戒指 | B123: 8_42984 | C123: 衔月戒 | D123: 30200 | E123: 衔月戒(30200速无) | F123: 8290 | G123: 676 | I123: 1536 | J123: 0 | K123: 0 | L123: 0 | M123: 0 | N123: 4522 | O123: 5652 | P123: 0 | R123: 0 | S123: 0 | T123: 速无 | U123: 6 | V123: 副本 | Z123: 1 | AA123: =IF(AND(D123>=配装计算器!$I$29,D123<=配装计算器!$I$30),1,0) -> 1 | AB123: =IF(J123>0,1,0) -> 0 | AC123: =IF(K123>0,1,0) -> 0 | AD123: =IF(L123>0,1,0) -> 0 | AE123: =IF(M123>0,1,0) -> 0 | AF123: =IF(N123>0,1,0) -> 1 | AG123: =IF(O123>0,1,0) -> 1 | AH123: =IF(P123>0,1,0) -> 0 | AI123: =IF(COUNTIF(T123,"*"&"精简"&"*")>0,1,0) -> 0 | AJ123: =MIN(1,AA123*($AY$2+IF(AND(AB123>=$AQ$3,AC123>=$AR$3,AD123>=$AS$3,AE123>=$AT$3,AF123>=$AU$3,AG123>=$AV$3,AH123>=$AW$3,AI123>=$AX$3),1,0))) -> 1 | AK123: =SUM(AJ$2:$AJ123) -> 122
A124: 戒指 | B124: 8_42879 | C124: 润源戒 | D124: 30200 | E124: 润源戒(30200会无) | F124: 8290 | G124: 676 | I124: 1536 | J124: 5652 | K124: 0 | L124: 0 | M124: 0 | N124: 4522 | O124: 0 | P124: 0 | R124: 0 | S124: 0 | T124: 会无 | U124: 6 | V124: 副本 | Z124: 1 | AA124: =IF(AND(D124>=配装计算器!$I$29,D124<=配装计算器!$I$30),1,0) -> 1 | AB124: =IF(J124>0,1,0) -> 1 | AC124: =IF(K124>0,1,0) -> 0 | AD124: =IF(L124>0,1,0) -> 0 | AE124: =IF(M124>0,1,0) -> 0 | AF124: =IF(N124>0,1,0) -> 1 | AG124: =IF(O124>0,1,0) -> 0 | AH124: =IF(P124>0,1,0) -> 0 | AI124: =IF(COUNTIF(T124,"*"&"精简"&"*")>0,1,0) -> 0 | AJ124: =MIN(1,AA124*($AY$2+IF(AND(AB124>=$AQ$3,AC124>=$AR$3,AD124>=$AS$3,AE124>=$AT$3,AF124>=$AU$3,AG124>=$AV$3,AH124>=$AW$3,AI124>=$AX$3),1,0))) -> 1 | AK124: =SUM(AJ$2:$AJ124) -> 123
A125: 戒指 | B125: 8_42972 | C125: 标雁戒 | D125: 30200 | E125: 标雁戒(30200会无) | F125: 8290 | G125: 676 | I125: 1536 | J125: 5652 | K125: 0 | L125: 0 | M125: 0 | N125: 4522 | O125: 0 | P125: 0 | R125: 0 | S125: 0 | T125: 会无 | U125: 6 | V125: 副本 | Z125: 1 | AA125: =IF(AND(D125>=配装计算器!$I$29,D125<=配装计算器!$I$30),1,0) -> 1 | AB125: =IF(J125>0,1,0) -> 1 | AC125: =IF(K125>0,1,0) -> 0 | AD125: =IF(L125>0,1,0) -> 0 | AE125: =IF(M125>0,1,0) -> 0 | AF125: =IF(N125>0,1,0) -> 1 | AG125: =IF(O125>0,1,0) -> 0 | AH125: =IF(P125>0,1,0) -> 0 | AI125: =IF(COUNTIF(T125,"*"&"精简"&"*")>0,1,0) -> 0 | AJ125: =MIN(1,AA125*($AY$2+IF(AND(AB125>=$AQ$3,AC125>=$AR$3,AD125>=$AS$3,AE125>=$AT$3,AF125>=$AU$3,AG125>=$AV$3,AH125>=$AW$3,AI125>=$AX$3),1,0))) -> 1 | AK125: =SUM(AJ$2:$AJ125) -> 124
A126: 戒指 | B126: 8_43072 | C126: 客行江湖·日斜指环 | D126: 30200 | E126: 客行江湖·日斜指环(30200破无) | F126: 8290 | G126: 676 | I126: 1536 | J126: 0 | K126: 0 | L126: 5652 | M126: 0 | N126: 4522 | O126: 0 | P126: 0 | R126: 0 | S126: 0 | T126: 破无 | U126: 6 | V126: 浪客笺 | Z126: 1 | AA126: =IF(AND(D126>=配装计算器!$I$29,D126<=配装计算器!$I$30),1,0) -> 1 | AB126: =IF(J126>0,1,0) -> 0 | AC126: =IF(K126>0,1,0) -> 0 | AD126: =IF(L126>0,1,0) -> 1 | AE126: =IF(M126>0,1,0) -> 0 | AF126: =IF(N126>0,1,0) -> 1 | AG126: =IF(O126>0,1,0) -> 0 | AH126: =IF(P126>0,1,0) -> 0 | AI126: =IF(COUNTIF(T126,"*"&"精简"&"*")>0,1,0) -> 0 | AJ126: =MIN(1,AA126*($AY$2+IF(AND(AB126>=$AQ$3,AC126>=$AR$3,AD126>=$AS$3,AE126>=$AT$3,AF126>=$AU$3,AG126>=$AV$3,AH126>=$AW$3,AI126>=$AX$3),1,0))) -> 1 | AK126: =SUM(AJ$2:$AJ126) -> 125
A127: 戒指 | B127: 8_43020 | C127: 溪畔行 | D127: 30200 | E127: 溪畔行(30200特效精简招无) | F127: 8290 | G127: 0 | I127: 1024 | J127: 0 | K127: 0 | L127: 0 | M127: 14696 | N127: 4522 | O127: 0 | P127: 0 | R127: 0 | S127: 0 | T127: 特效精简招无 | U127: 6 | V127: 副本 | Z127: 1 | AA127: =IF(AND(D127>=配装计算器!$I$29,D127<=配装计算器!$I$30),1,0) -> 1 | AB127: =IF(J127>0,1,0) -> 0 | AC127: =IF(K127>0,1,0) -> 0 | AD127: =IF(L127>0,1,0) -> 0 | AE127: =IF(M127>0,1,0) -> 1 | AF127: =IF(N127>0,1,0) -> 1 | AG127: =IF(O127>0,1,0) -> 0 | AH127: =IF(P127>0,1,0) -> 0 | AI127: =IF(COUNTIF(T127,"*"&"精简"&"*")>0,1,0) -> 1 | AJ127: =MIN(1,AA127*($AY$2+IF(AND(AB127>=$AQ$3,AC127>=$AR$3,AD127>=$AS$3,AE127>=$AT$3,AF127>=$AU$3,AG127>=$AV$3,AH127>=$AW$3,AI127>=$AX$3),1,0))) -> 1 | AK127: =SUM(AJ$2:$AJ127) -> 126
A128: 戒指 | B128: 8_43019 | C128: 芳洲曲 | D128: 30200 | E128: 芳洲曲(30200特效精简破无) | F128: 8290 | G128: 0 | I128: 1024 | J128: 0 | K128: 0 | L128: 14696 | M128: 0 | N128: 4522 | O128: 0 | P128: 0 | R128: 0 | S128: 0 | T128: 特效精简破无 | U128: 6 | V128: 副本 | Z128: 1 | AA128: =IF(AND(D128>=配装计算器!$I$29,D128<=配装计算器!$I$30),1,0) -> 1 | AB128: =IF(J128>0,1,0) -> 0 | AC128: =IF(K128>0,1,0) -> 0 | AD128: =IF(L128>0,1,0) -> 1 | AE128: =IF(M128>0,1,0) -> 0 | AF128: =IF(N128>0,1,0) -> 1 | AG128: =IF(O128>0,1,0) -> 0 | AH128: =IF(P128>0,1,0) -> 0 | AI128: =IF(COUNTIF(T128,"*"&"精简"&"*")>0,1,0) -> 1 | AJ128: =MIN(1,AA128*($AY$2+IF(AND(AB128>=$AQ$3,AC128>=$AR$3,AD128>=$AS$3,AE128>=$AT$3,AF128>=$AU$3,AG128>=$AV$3,AH128>=$AW$3,AI128>=$AX$3),1,0))) -> 1 | AK128: =SUM(AJ$2:$AJ128) -> 127
...

Sheet 装备选择
A1: 部位 | B1: 装备ID | C1: 显示名称 | E1: 0 | G1: =ROW() -> 1 | H1: 暗器 | I1: =MATCH(H1,$A$2:$A$2001,0) -> 1 | J1: =COUNTIF($A$2:$A$2665,H1) -> 41 | M1: 部位 | N1: 选择 | O1: 精炼等级 | P1: 最大精炼等级 | Q1: 实际精炼等级 | R1: 孔1 | S1: 孔2 | T1: 孔3 | U1: 来源 | V1: 体质 | W1: 身法 | X1: 力道 | Y1: 攻击 | Z1: 会心 | AA1: 会效 | AB1: 破防 | AC1: 破招 | AD1: 无双 | AE1: 加速 | AF1: 全能 | AG1: 御劲 | AH1: 武器伤害 | AI1: 武器伤害2 | AJ1: 精炼体质 | AK1: 精炼身法 | AL1: 精炼力道 | AM1: 精炼攻击 | AN1: 精炼会心 | AO1: 精炼会效 | AP1: 精炼破防 | AQ1: 精炼破招 | AR1: 精炼无双 | AS1: 精炼加速 | AT1: 精炼全能 | AU1: 精炼御劲 | AV1: ="最终"&V1 -> 最终体质 | AW1: ="最终"&W1 -> 最终身法 | AX1: ="最终"&X1 -> 最终力道 | AY1: ="最终"&Y1 -> 最终攻击 | AZ1: ="最终"&Z1 -> 最终会心 | BA1: ="最终"&AA1 -> 最终会效 | BB1: ="最终"&AB1 -> 最终破防 | BC1: ="最终"&AC1 -> 最终破招 | ... BI1: ="最终"&AI1 -> 最终武器伤害2 | BJ1: 装备等级 | BK1: 品质系数 | BL1: 装备系数 | BM1: 装备分数 | BN1: 精炼分数
A2: =IFERROR(INDEX(装备库!$A$2:$E$2022,MATCH(ROW()-1,装备库!$AK$2:$AK$2022,0),COLUMN()),"") -> 暗器 | B2: =IFERROR(INDEX(装备库!$A$2:$E$2022,MATCH(ROW()-1,装备库!$AK$2:$AK$2022,0),COLUMN()),"") -> 6_43603 | C2: =IFERROR(INDEX(装备库!$A$2:$E$2022,MATCH(ROW()-1,装备库!$AK$2:$AK$2022,0),5),"") -> 智渊囊(30200破全) | E2: 1 | G2: =ROW() -> 2 | H2: 护手 | I2: =IFERROR(MATCH(H2,$A$2:$A$2000,0),I1) -> 42 | J2: =COUNTIF($A$2:$A$2665,H2) -> 75 | M2: 帽子 | N2: =配装计算器!C2 -> 无修冠·外·天(41400特效精简会无) | O2: =IFERROR(1*$N$20,配装计算器!C3) -> 6 | P2: =IFERROR(INDEX(装备库!$A$1:$Z$2022,MATCH($N2,装备库!$E$1:$E$2022,0),COLUMN(装备库!$U$1)),0) -> 6 | Q2: =MIN(O2,P2) -> 6 | R2: =IF(IFERROR(INDEX(装备库!$A$1:$Z$2022,MATCH($N2,装备库!$E$1:$E$2022,0),COLUMN(装备库!W$1)),"")=0,"",IFERROR(INDEX(装备库!$A$1:$Z$2022,MATCH($N2,装备库!$E$1:$E$2022,0),COLUMN(装备库!W$1)),"")) -> 攻击孔 | S2: =IF(IFERROR(INDEX(装备库!$A$1:$Z$2022,MATCH($N2,装备库!$E$1:$E$2022,0),COLUMN(装备库!X$1)),"")=0,"",IFERROR(INDEX(装备库!$A$1:$Z$2022,MATCH($N2,装备库!$E$1:$E$2022,0),COLUMN(装备库!X$1)),"")) -> 无双孔 | T2: =IF(IFERROR(INDEX(装备库!$A$1:$Z$2022,MATCH($N2,装备库!$E$1:$E$2022,0),COLUMN(装备库!Y$1)),"")=0,"",IFERROR(INDEX(装备库!$A$1:$Z$2022,MATCH($N2,装备库!$E$1:$E$2022,0),COLUMN(装备库!Y$1)),"")) | U2: =IFERROR(INDEX(装备库!$A$1:$Z$2022,MATCH($N2,装备库!$E$1:$E$2022,0),COLUMN(装备库!$V$1)),"") -> 活动 | V2: =IFERROR(INDEX(装备库!$A$1:$Z$2022,MATCH($N2,装备库!$E$1:$E$2022,0),COLUMN(装备库!F$1)),0) -> 20456 | W2: =IFERROR(INDEX(装备库!$A$1:$Z$2022,MATCH($N2,装备库!$E$1:$E$2022,0),COLUMN(装备库!G$1)),0) -> 0 | X2: =IFERROR(INDEX(装备库!$A$1:$Z$2022,MATCH($N2,装备库!$E$1:$E$2022,0),COLUMN(装备库!H$1)),0) -> 0 | Y2: =IFERROR(INDEX(装备库!$A$1:$Z$2022,MATCH($N2,装备库!$E$1:$E$2022,0),COLUMN(装备库!I$1)),0) -> 2527 | Z2: =IFERROR(INDEX(装备库!$A$1:$Z$2022,MATCH($N2,装备库!$E$1:$E$2022,0),COLUMN(装备库!J$1)),0) -> 36262 | AA2: =IFERROR(INDEX(装备库!$A$1:$Z$2022,MATCH($N2,装备库!$E$1:$E$2022,0),COLUMN(装备库!K$1)),0) -> 0 | AB2: =IFERROR(INDEX(装备库!$A$1:$Z$2022,MATCH($N2,装备库!$E$1:$E$2022,0),COLUMN(装备库!L$1)),0) -> 0 | AC2: =IFERROR(INDEX(装备库!$A$1:$Z$2022,MATCH($N2,装备库!$E$1:$E$2022,0),COLUMN(装备库!M$1)),0) -> 0 | ... AI2: =IFERROR(INDEX(装备库!$A$1:$Z$2022,MATCH($N2,装备库!$E$1:$E$2022,0),COLUMN(装备库!S$1)),0) -> 0 | AJ2: =ROUND(V2*(CHOOSE($Q2+1,1,1.005,1.013,1.024,1.038,1.055,1.075,1.098,1.124)-1),0) -> 1534 | AK2: =ROUND(W2*(CHOOSE($Q2+1,1,1.005,1.013,1.024,1.038,1.055,1.075,1.098,1.124)-1),0) -> 0 | AL2: =ROUND(X2*(CHOOSE($Q2+1,1,1.005,1.013,1.024,1.038,1.055,1.075,1.098,1.124)-1),0) -> 0 | AM2: =ROUND(Y2*(CHOOSE($Q2+1,1,1.005,1.013,1.024,1.038,1.055,1.075,1.098,1.124)-1),0) -> 190 | AN2: =ROUND(Z2*(CHOOSE($Q2+1,1,1.005,1.013,1.024,1.038,1.055,1.075,1.098,1.124)-1),0) -> 2720 | AO2: =ROUND(AA2*(CHOOSE($Q2+1,1,1.005,1.013,1.024,1.038,1.055,1.075,1.098,1.124)-1),0) -> 0 | AP2: =ROUND(AB2*(CHOOSE($Q2+1,1,1.005,1.013,1.024,1.038,1.055,1.075,1.098,1.124)-1),0) -> 0 | AQ2: =ROUND(AC2*(CHOOSE($Q2+1,1,1.005,1.013,1.024,1.038,1.055,1.075,1.098,1.124)-1),0) -> 0 | ... AU2: =ROUND(AG2*(CHOOSE($Q2+1,1,1.005,1.013,1.024,1.038,1.055,1.075,1.098,1.124)-1),0) -> 0 | AV2: =AJ2+V2 -> 21990 | AW2: =AK2+W2 -> 0 | AX2: =AL2+X2 -> 0 | AY2: =AM2+Y2 -> 2717 | AZ2: =AN2+Z2 -> 38982 | BA2: =AO2+AA2 -> 0 | BB2: =AP2+AB2 -> 0 | BC2: =AQ2+AC2 -> 0 | ... BG2: =AU2+AG2 -> 0 | BH2: =AH2 -> 0 | BI2: =AI2 -> 0 | BJ2: =IFERROR(INDEX(装备库!$A$1:$Z$2022,MATCH($N2,装备库!$E$1:$E$2022,0),COLUMN(装备库!$D$1)),0) -> 41400 | BK2: =IF(P2=8,2,1.8) -> 1.8 | BL2: 0.9 | BM2: =ROUND(BJ2*BK2*BL2,0) -> 67068 | BN2: =ROUND(BM2*(CHOOSE($Q2+1,1,1.005,1.013,1.024,1.038,1.055,1.075,1.098,1.124)-1),0) -> 5030
A3: =IFERROR(INDEX(装备库!$A$2:$E$2022,MATCH(ROW()-1,装备库!$AK$2:$AK$2022,0),COLUMN()),"") -> 暗器 | B3: =IFERROR(INDEX(装备库!$A$2:$E$2022,MATCH(ROW()-1,装备库!$AK$2:$AK$2022,0),COLUMN()),"") -> 6_43641 | C3: =IFERROR(INDEX(装备库!$A$2:$E$2022,MATCH(ROW()-1,装备库!$AK$2:$AK$2022,0),5),"") -> 镂云囊(30200会全) | E3: 2 | G3: =ROW() -> 3 | H3: 戒指 | I3: =IFERROR(MATCH(H3,$A$2:$A$2000,0),I2) -> 117 | J3: =COUNTIF($A$2:$A$2665,H3) -> 67 | M3: 上衣 | N3: =配装计算器!C7 -> 【门派套装】玄阙·燃炼衣(41400会无) | O3: =IFERROR(1*$N$20,配装计算器!C8) -> 6 | P3: =IFERROR(INDEX(装备库!$A$1:$Z$2022,MATCH($N3,装备库!$E$1:$E$2022,0),COLUMN(装备库!$U$1)),0) -> 6 | Q3: =MIN(O3,P3) -> 6 | R3: =IF(IFERROR(INDEX(装备库!$A$1:$Z$2022,MATCH($N3,装备库!$E$1:$E$2022,0),COLUMN(装备库!W$1)),"")=0,"",IFERROR(INDEX(装备库!$A$1:$Z$2022,MATCH($N3,装备库!$E$1:$E$2022,0),COLUMN(装备库!W$1)),"")) -> 会心孔 | S3: =IF(IFERROR(INDEX(装备库!$A$1:$Z$2022,MATCH($N3,装备库!$E$1:$E$2022,0),COLUMN(装备库!X$1)),"")=0,"",IFERROR(INDEX(装备库!$A$1:$Z$2022,MATCH($N3,装备库!$E$1:$E$2022,0),COLUMN(装备库!X$1)),"")) -> 会效孔 | T3: =IF(IFERROR(INDEX(装备库!$A$1:$Z$2022,MATCH($N3,装备库!$E$1:$E$2022,0),COLUMN(装备库!Y$1)),"")=0,"",IFERROR(INDEX(装备库!$A$1:$Z$2022,MATCH($N3,装备库!$E$1:$E$2022,0),COLUMN(装备库!Y$1)),"")) | U3: =IFERROR(INDEX(装备库!$A$1:$Z$2022,MATCH($N3,装备库!$E$1:$E$2022,0),COLUMN(装备库!$V$1)),"") -> 兑换牌 | V3: =IFERROR(INDEX(装备库!$A$1:$Z$2022,MATCH($N3,装备库!$E$1:$E$2022,0),COLUMN(装备库!F$1)),0) -> 22729 | W3: =IFERROR(INDEX(装备库!$A$1:$Z$2022,MATCH($N3,装备库!$E$1:$E$2022,0),COLUMN(装备库!G$1)),0) -> 1854 | X3: =IFERROR(INDEX(装备库!$A$1:$Z$2022,MATCH($N3,装备库!$E$1:$E$2022,0),COLUMN(装备库!H$1)),0) -> 0 | Y3: =IFERROR(INDEX(装备库!$A$1:$Z$2022,MATCH($N3,装备库!$E$1:$E$2022,0),COLUMN(装备库!I$1)),0) -> 4211 | Z3: =IFERROR(INDEX(装备库!$A$1:$Z$2022,MATCH($N3,装备库!$E$1:$E$2022,0),COLUMN(装备库!J$1)),0) -> 15497 | AA3: =IFERROR(INDEX(装备库!$A$1:$Z$2022,MATCH($N3,装备库!$E$1:$E$2022,0),COLUMN(装备库!K$1)),0) -> 0 | AB3: =IFERROR(INDEX(装备库!$A$1:$Z$2022,MATCH($N3,装备库!$E$1:$E$2022,0),COLUMN(装备库!L$1)),0) -> 0 | AC3: =IFERROR(INDEX(装备库!$A$1:$Z$2022,MATCH($N3,装备库!$E$1:$E$2022,0),COLUMN(装备库!M$1)),0) -> 0 | ... AI3: =IFERROR(INDEX(装备库!$A$1:$Z$2022,MATCH($N3,装备库!$E$1:$E$2022,0),COLUMN(装备库!S$1)),0) -> 0 | AJ3: =ROUND(V3*(CHOOSE($Q3+1,1,1.005,1.013,1.024,1.038,1.055,1.075,1.098,1.124)-1),0) -> 1705 | AK3: =ROUND(W3*(CHOOSE($Q3+1,1,1.005,1.013,1.024,1.038,1.055,1.075,1.098,1.124)-1),0) -> 139 | AL3: =ROUND(X3*(CHOOSE($Q3+1,1,1.005,1.013,1.024,1.038,1.055,1.075,1.098,1.124)-1),0) -> 0 | AM3: =ROUND(Y3*(CHOOSE($Q3+1,1,1.005,1.013,1.024,1.038,1.055,1.075,1.098,1.124)-1),0) -> 316 | AN3: =ROUND(Z3*(CHOOSE($Q3+1,1,1.005,1.013,1.024,1.038,1.055,1.075,1.098,1.124)-1),0) -> 1162 | AO3: =ROUND(AA3*(CHOOSE($Q3+1,1,1.005,1.013,1.024,1.038,1.055,1.075,1.098,1.124)-1),0) -> 0 | AP3: =ROUND(AB3*(CHOOSE($Q3+1,1,1.005,1.013,1.024,1.038,1.055,1.075,1.098,1.124)-1),0) -> 0 | AQ3: =ROUND(AC3*(CHOOSE($Q3+1,1,1.005,1.013,1.024,1.038,1.055,1.075,1.098,1.124)-1),0) -> 0 | ... AU3: =ROUND(AG3*(CHOOSE($Q3+1,1,1.005,1.013,1.024,1.038,1.055,1.075,1.098,1.124)-1),0) -> 0 | AV3: =AJ3+V3 -> 24434 | AW3: =AK3+W3 -> 1993 | AX3: =AL3+X3 -> 0 | AY3: =AM3+Y3 -> 4527 | AZ3: =AN3+Z3 -> 16659 | BA3: =AO3+AA3 -> 0 | BB3: =AP3+AB3 -> 0 | BC3: =AQ3+AC3 -> 0 | ... BG3: =AU3+AG3 -> 0 | BH3: =AH3 -> 0 | BI3: =AI3 -> 0 | BJ3: =IFERROR(INDEX(装备库!$A$1:$Z$2022,MATCH($N3,装备库!$E$1:$E$2022,0),COLUMN(装备库!$D$1)),0) -> 41400 | BK3: =IF(P3=8,2,1.8) -> 1.8 | BL3: 1 | BM3: =ROUND(BJ3*BK3*BL3,0) -> 74520 | BN3: =ROUND(BM3*(CHOOSE($Q3+1,1,1.005,1.013,1.024,1.038,1.055,1.075,1.098,1.124)-1),0) -> 5589
A4: =IFERROR(INDEX(装备库!$A$2:$E$2022,MATCH(ROW()-1,装备库!$AK$2:$AK$2022,0),COLUMN()),"") -> 暗器 | B4: =IFERROR(INDEX(装备库!$A$2:$E$2022,MATCH(ROW()-1,装备库!$AK$2:$AK$2022,0),COLUMN()),"") -> 6_45633 | C4: =IFERROR(INDEX(装备库!$A$2:$E$2022,MATCH(ROW()-1,装备库!$AK$2:$AK$2022,0),5),"") -> 臻泽囊(30200会全) | E4: 3 | G4: =ROW() -> 4 | H4: 裤子 | I4: =IFERROR(MATCH(H4,$A$2:$A$2000,0),I3) -> 184 | J4: =COUNTIF($A$2:$A$2665,H4) -> 75 | M4: 腰带 | N4: =配装计算器!C12 -> 凌月游(41400特效精简破无) | O4: =IFERROR(1*$N$20,配装计算器!C13) -> 6 | P4: =IFERROR(INDEX(装备库!$A$1:$Z$2022,MATCH($N4,装备库!$E$1:$E$2022,0),COLUMN(装备库!$U$1)),0) -> 6 | Q4: =MIN(O4,P4) -> 6 | R4: =IF(IFERROR(INDEX(装备库!$A$1:$Z$2022,MATCH($N4,装备库!$E$1:$E$2022,0),COLUMN(装备库!W$1)),"")=0,"",IFERROR(INDEX(装备库!$A$1:$Z$2022,MATCH($N4,装备库!$E$1:$E$2022,0),COLUMN(装备库!W$1)),"")) -> 破防孔 | S4: =IF(IFERROR(INDEX(装备库!$A$1:$Z$2022,MATCH($N4,装备库!$E$1:$E$2022,0),COLUMN(装备库!X$1)),"")=0,"",IFERROR(INDEX(装备库!$A$1:$Z$2022,MATCH($N4,装备库!$E$1:$E$2022,0),COLUMN(装备库!X$1)),"")) -> 攻击孔 | T4: =IF(IFERROR(INDEX(装备库!$A$1:$Z$2022,MATCH($N4,装备库!$E$1:$E$2022,0),COLUMN(装备库!Y$1)),"")=0,"",IFERROR(INDEX(装备库!$A$1:$Z$2022,MATCH($N4,装备库!$E$1:$E$2022,0),COLUMN(装备库!Y$1)),"")) | U4: =IFERROR(INDEX(装备库!$A$1:$Z$2022,MATCH($N4,装备库!$E$1:$E$2022,0),COLUMN(装备库!$V$1)),"") -> 副本 | V4: =IFERROR(INDEX(装备库!$A$1:$Z$2022,MATCH($N4,装备库!$E$1:$E$2022,0),COLUMN(装备库!F$1)),0) -> 15910 | W4: =IFERROR(INDEX(装备库!$A$1:$Z$2022,MATCH($N4,装备库!$E$1:$E$2022,0),COLUMN(装备库!G$1)),0) -> 0 | X4: =IFERROR(INDEX(装备库!$A$1:$Z$2022,MATCH($N4,装备库!$E$1:$E$2022,0),COLUMN(装备库!H$1)),0) -> 0 | Y4: =IFERROR(INDEX(装备库!$A$1:$Z$2022,MATCH($N4,装备库!$E$1:$E$2022,0),COLUMN(装备库!I$1)),0) -> 1965 | Z4: =IFERROR(INDEX(装备库!$A$1:$Z$2022,MATCH($N4,装备库!$E$1:$E$2022,0),COLUMN(装备库!J$1)),0) -> 0 | AA4: =IFERROR(INDEX(装备库!$A$1:$Z$2022,MATCH($N4,装备库!$E$1:$E$2022,0),COLUMN(装备库!K$1)),0) -> 0 | AB4: =IFERROR(INDEX(装备库!$A$1:$Z$2022,MATCH($N4,装备库!$E$1:$E$2022,0),COLUMN(装备库!L$1)),0) -> 28204 | AC4: =IFERROR(INDEX(装备库!$A$1:$Z$2022,MATCH($N4,装备库!$E$1:$E$2022,0),COLUMN(装备库!M$1)),0) -> 0 | ... AI4: =IFERROR(INDEX(装备库!$A$1:$Z$2022,MATCH($N4,装备库!$E$1:$E$2022,0),COLUMN(装备库!S$1)),0) -> 0 | AJ4: =ROUND(V4*(CHOOSE($Q4+1,1,1.005,1.013,1.024,1.038,1.055,1.075,1.098,1.124)-1),0) -> 1193 | AK4: =ROUND(W4*(CHOOSE($Q4+1,1,1.005,1.013,1.024,1.038,1.055,1.075,1.098,1.124)-1),0) -> 0 | AL4: =ROUND(X4*(CHOOSE($Q4+1,1,1.005,1.013,1.024,1.038,1.055,1.075,1.098,1.124)-1),0) -> 0 | AM4: =ROUND(Y4*(CHOOSE($Q4+1,1,1.005,1.013,1.024,1.038,1.055,1.075,1.098,1.124)-1),0) -> 147 | AN4: =ROUND(Z4*(CHOOSE($Q4+1,1,1.005,1.013,1.024,1.038,1.055,1.075,1.098,1.124)-1),0) -> 0 | AO4: =ROUND(AA4*(CHOOSE($Q4+1,1,1.005,1.013,1.024,1.038,1.055,1.075,1.098,1.124)-1),0) -> 0 | AP4: =ROUND(AB4*(CHOOSE($Q4+1,1,1.005,1.013,1.024,1.038,1.055,1.075,1.098,1.124)-1),0) -> 2115 | AQ4: =ROUND(AC4*(CHOOSE($Q4+1,1,1.005,1.013,1.024,1.038,1.055,1.075,1.098,1.124)-1),0) -> 0 | ... AU4: =ROUND(AG4*(CHOOSE($Q4+1,1,1.005,1.013,1.024,1.038,1.055,1.075,1.098,1.124)-1),0) -> 0 | AV4: =AJ4+V4 -> 17103 | AW4: =AK4+W4 -> 0 | AX4: =AL4+X4 -> 0 | AY4: =AM4+Y4 -> 2112 | AZ4: =AN4+Z4 -> 0 | BA4: =AO4+AA4 -> 0 | BB4: =AP4+AB4 -> 30319 | BC4: =AQ4+AC4 -> 0 | ... BG4: =AU4+AG4 -> 0 | BH4: =AH4 -> 0 | BI4: =AI4 -> 0 | BJ4: =IFERROR(INDEX(装备库!$A$1:$Z$2022,MATCH($N4,装备库!$E$1:$E$2022,0),COLUMN(装备库!$D$1)),0) -> 41400 | BK4: =IF(P4=8,2,1.8) -> 1.8 | BL4: 0.7 | BM4: =ROUND(BJ4*BK4*BL4,0) -> 52164 | BN4: =ROUND(BM4*(CHOOSE($Q4+1,1,1.005,1.013,1.024,1.038,1.055,1.075,1.098,1.124)-1),0) -> 3912
A5: =IFERROR(INDEX(装备库!$A$2:$E$2022,MATCH(ROW()-1,装备库!$AK$2:$AK$2022,0),COLUMN()),"") -> 暗器 | B5: =IFERROR(INDEX(装备库!$A$2:$E$2022,MATCH(ROW()-1,装备库!$AK$2:$AK$2022,0),COLUMN()),"") -> 6_43372 | C5: =IFERROR(INDEX(装备库!$A$2:$E$2022,MATCH(ROW()-1,装备库!$AK$2:$AK$2022,0),5),"") -> 孤城惊梦·迷烟囊(30200会无) | E5: 4 | G5: =ROW() -> 5 | H5: 帽子 | I5: =IFERROR(MATCH(H5,$A$2:$A$2000,0),I4) -> 259 | J5: =COUNTIF($A$2:$A$2665,H5) -> 46 | M5: 护手 | N5: =配装计算器!I2 -> 野渡护腕·引(41400精简招无) | O5: =IFERROR(1*$N$20,配装计算器!I3) -> 6 | P5: =IFERROR(INDEX(装备库!$A$1:$Z$2022,MATCH($N5,装备库!$E$1:$E$2022,0),COLUMN(装备库!$U$1)),0) -> 6 | Q5: =MIN(O5,P5) -> 6 | R5: =IF(IFERROR(INDEX(装备库!$A$1:$Z$2022,MATCH($N5,装备库!$E$1:$E$2022,0),COLUMN(装备库!W$1)),"")=0,"",IFERROR(INDEX(装备库!$A$1:$Z$2022,MATCH($N5,装备库!$E$1:$E$2022,0),COLUMN(装备库!W$1)),"")) -> 破招孔 | S5: =IF(IFERROR(INDEX(装备库!$A$1:$Z$2022,MATCH($N5,装备库!$E$1:$E$2022,0),COLUMN(装备库!X$1)),"")=0,"",IFERROR(INDEX(装备库!$A$1:$Z$2022,MATCH($N5,装备库!$E$1:$E$2022,0),COLUMN(装备库!X$1)),"")) -> 无双孔 | T5: =IF(IFERROR(INDEX(装备库!$A$1:$Z$2022,MATCH($N5,装备库!$E$1:$E$2022,0),COLUMN(装备库!Y$1)),"")=0,"",IFERROR(INDEX(装备库!$A$1:$Z$2022,MATCH($N5,装备库!$E$1:$E$2022,0),COLUMN(装备库!Y$1)),"")) | U5: =IFERROR(INDEX(装备库!$A$1:$Z$2022,MATCH($N5,装备库!$E$1:$E$2022,0),COLUMN(装备库!$V$1)),"") -> 副本 | V5: =IFERROR(INDEX(装备库!$A$1:$Z$2022,MATCH($N5,装备库!$E$1:$E$2022,0),COLUMN(装备库!F$1)),0) -> 15910 | W5: =IFERROR(INDEX(装备库!$A$1:$Z$2022,MATCH($N5,装备库!$E$1:$E$2022,0),COLUMN(装备库!G$1)),0) -> 0 | X5: =IFERROR(INDEX(装备库!$A$1:$Z$2022,MATCH($N5,装备库!$E$1:$E$2022,0),COLUMN(装备库!H$1)),0) -> 0 | Y5: =IFERROR(INDEX(装备库!$A$1:$Z$2022,MATCH($N5,装备库!$E$1:$E$2022,0),COLUMN(装备库!I$1)),0) -> 3931 | Z5: =IFERROR(INDEX(装备库!$A$1:$Z$2022,MATCH($N5,装备库!$E$1:$E$2022,0),COLUMN(装备库!J$1)),0) -> 0 | AA5: =IFERROR(INDEX(装备库!$A$1:$Z$2022,MATCH($N5,装备库!$E$1:$E$2022,0),COLUMN(装备库!K$1)),0) -> 0 | AB5: =IFERROR(INDEX(装备库!$A$1:$Z$2022,MATCH($N5,装备库!$E$1:$E$2022,0),COLUMN(装备库!L$1)),0) -> 0 | AC5: =IFERROR(INDEX(装备库!$A$1:$Z$2022,MATCH($N5,装备库!$E$1:$E$2022,0),COLUMN(装备库!M$1)),0) -> 20611 | ... AI5: =IFERROR(INDEX(装备库!$A$1:$Z$2022,MATCH($N5,装备库!$E$1:$E$2022,0),COLUMN(装备库!S$1)),0) -> 0 | AJ5: =ROUND(V5*(CHOOSE($Q5+1,1,1.005,1.013,1.024,1.038,1.055,1.075,1.098,1.124)-1),0) -> 1193 | AK5: =ROUND(W5*(CHOOSE($Q5+1,1,1.005,1.013,1.024,1.038,1.055,1.075,1.098,1.124)-1),0) -> 0 | AL5: =ROUND(X5*(CHOOSE($Q5+1,1,1.005,1.013,1.024,1.038,1.055,1.075,1.098,1.124)-1),0) -> 0 | AM5: =ROUND(Y5*(CHOOSE($Q5+1,1,1.005,1.013,1.024,1.038,1.055,1.075,1.098,1.124)-1),0) -> 295 | AN5: =ROUND(Z5*(CHOOSE($Q5+1,1,1.005,1.013,1.024,1.038,1.055,1.075,1.098,1.124)-1),0) -> 0 | AO5: =ROUND(AA5*(CHOOSE($Q5+1,1,1.005,1.013,1.024,1.038,1.055,1.075,1.098,1.124)-1),0) -> 0 | AP5: =ROUND(AB5*(CHOOSE($Q5+1,1,1.005,1.013,1.024,1.038,1.055,1.075,1.098,1.124)-1),0) -> 0 | AQ5: =ROUND(AC5*(CHOOSE($Q5+1,1,1.005,1.013,1.024,1.038,1.055,1.075,1.098,1.124)-1),0) -> 1546 | ... AU5: =ROUND(AG5*(CHOOSE($Q5+1,1,1.005,1.013,1.024,1.038,1.055,1.075,1.098,1.124)-1),0) -> 0 | AV5: =AJ5+V5 -> 17103 | AW5: =AK5+W5 -> 0 | AX5: =AL5+X5 -> 0 | AY5: =AM5+Y5 -> 4226 | AZ5: =AN5+Z5 -> 0 | BA5: =AO5+AA5 -> 0 | BB5: =AP5+AB5 -> 0 | BC5: =AQ5+AC5 -> 22157 | ... BG5: =AU5+AG5 -> 0 | BH5: =AH5 -> 0 | BI5: =AI5 -> 0 | BJ5: =IFERROR(INDEX(装备库!$A$1:$Z$2022,MATCH($N5,装备库!$E$1:$E$2022,0),COLUMN(装备库!$D$1)),0) -> 41400 | BK5: =IF(P5=8,2,1.8) -> 1.8 | BL5: 0.7 | BM5: =ROUND(BJ5*BK5*BL5,0) -> 52164 | BN5: =ROUND(BM5*(CHOOSE($Q5+1,1,1.005,1.013,1.024,1.038,1.055,1.075,1.098,1.124)-1),0) -> 3912
A6: =IFERROR(INDEX(装备库!$A$2:$E$2022,MATCH(ROW()-1,装备库!$AK$2:$AK$2022,0),COLUMN()),"") -> 暗器 | B6: =IFERROR(INDEX(装备库!$A$2:$E$2022,MATCH(ROW()-1,装备库!$AK$2:$AK$2022,0),COLUMN()),"") -> 6_40579 | C6: =IFERROR(INDEX(装备库!$A$2:$E$2022,MATCH(ROW()-1,装备库!$AK$2:$AK$2022,0),5),"") -> 羽缀囊(30200招无) | E6: 5 | G6: =ROW() -> 6 | H6: 轻剑 | I6: =IFERROR(MATCH(H6,$A$2:$A$2000,0),I5) -> 305 | J6: =COUNTIF($A$2:$A$2665,H6) -> 49 | M6: 裤子 | N6: =配装计算器!I7 -> 停日裤·明(41400精简会招无) | O6: =IFERROR(1*$N$20,配装计算器!I8) -> 6 | P6: =IFERROR(INDEX(装备库!$A$1:$Z$2022,MATCH($N6,装备库!$E$1:$E$2022,0),COLUMN(装备库!$U$1)),0) -> 6 | Q6: =MIN(O6,P6) -> 6 | R6: =IF(IFERROR(INDEX(装备库!$A$1:$Z$2022,MATCH($N6,装备库!$E$1:$E$2022,0),COLUMN(装备库!W$1)),"")=0,"",IFERROR(INDEX(装备库!$A$1:$Z$2022,MATCH($N6,装备库!$E$1:$E$2022,0),COLUMN(装备库!W$1)),"")) -> 会心孔 | S6: =IF(IFERROR(INDEX(装备库!$A$1:$Z$2022,MATCH($N6,装备库!$E$1:$E$2022,0),COLUMN(装备库!X$1)),"")=0,"",IFERROR(INDEX(装备库!$A$1:$Z$2022,MATCH($N6,装备库!$E$1:$E$2022,0),COLUMN(装备库!X$1)),"")) -> 无双孔 | T6: =IF(IFERROR(INDEX(装备库!$A$1:$Z$2022,MATCH($N6,装备库!$E$1:$E$2022,0),COLUMN(装备库!Y$1)),"")=0,"",IFERROR(INDEX(装备库!$A$1:$Z$2022,MATCH($N6,装备库!$E$1:$E$2022,0),COLUMN(装备库!Y$1)),"")) | U6: =IFERROR(INDEX(装备库!$A$1:$Z$2022,MATCH($N6,装备库!$E$1:$E$2022,0),COLUMN(装备库!$V$1)),"") -> 副本 | V6: =IFERROR(INDEX(装备库!$A$1:$Z$2022,MATCH($N6,装备库!$E$1:$E$2022,0),COLUMN(装备库!F$1)),0) -> 22729 | W6: =IFERROR(INDEX(装备库!$A$1:$Z$2022,MATCH($N6,装备库!$E$1:$E$2022,0),COLUMN(装备库!G$1)),0) -> 0 | X6: =IFERROR(INDEX(装备库!$A$1:$Z$2022,MATCH($N6,装备库!$E$1:$E$2022,0),COLUMN(装备库!H$1)),0) -> 0 | Y6: =IFERROR(INDEX(装备库!$A$1:$Z$2022,MATCH($N6,装备库!$E$1:$E$2022,0),COLUMN(装备库!I$1)),0) -> 8142 | Z6: =IFERROR(INDEX(装备库!$A$1:$Z$2022,MATCH($N6,装备库!$E$1:$E$2022,0),COLUMN(装备库!J$1)),0) -> 11364 | AA6: =IFERROR(INDEX(装备库!$A$1:$Z$2022,MATCH($N6,装备库!$E$1:$E$2022,0),COLUMN(装备库!K$1)),0) -> 0 | AB6: =IFERROR(INDEX(装备库!$A$1:$Z$2022,MATCH($N6,装备库!$E$1:$E$2022,0),COLUMN(装备库!L$1)),0) -> 0 | AC6: =IFERROR(INDEX(装备库!$A$1:$Z$2022,MATCH($N6,装备库!$E$1:$E$2022,0),COLUMN(装备库!M$1)),0) -> 11364 | ... AI6: =IFERROR(INDEX(装备库!$A$1:$Z$2022,MATCH($N6,装备库!$E$1:$E$2022,0),COLUMN(装备库!S$1)),0) -> 0 | AJ6: =ROUND(V6*(CHOOSE($Q6+1,1,1.005,1.013,1.024,1.038,1.055,1.075,1.098,1.124)-1),0) -> 1705 | AK6: =ROUND(W6*(CHOOSE($Q6+1,1,1.005,1.013,1.024,1.038,1.055,1.075,1.098,1.124)-1),0) -> 0 | AL6: =ROUND(X6*(CHOOSE($Q6+1,1,1.005,1.013,1.024,1.038,1.055,1.075,1.098,1.124)-1),0) -> 0 | AM6: =ROUND(Y6*(CHOOSE($Q6+1,1,1.005,1.013,1.024,1.038,1.055,1.075,1.098,1.124)-1),0) -> 611 | AN6: =ROUND(Z6*(CHOOSE($Q6+1,1,1.005,1.013,1.024,1.038,1.055,1.075,1.098,1.124)-1),0) -> 852 | AO6: =ROUND(AA6*(CHOOSE($Q6+1,1,1.005,1.013,1.024,1.038,1.055,1.075,1.098,1.124)-1),0) -> 0 | AP6: =ROUND(AB6*(CHOOSE($Q6+1,1,1.005,1.013,1.024,1.038,1.055,1.075,1.098,1.124)-1),0) -> 0 | AQ6: =ROUND(AC6*(CHOOSE($Q6+1,1,1.005,1.013,1.024,1.038,1.055,1.075,1.098,1.124)-1),0) -> 852 | ... AU6: =ROUND(AG6*(CHOOSE($Q6+1,1,1.005,1.013,1.024,1.038,1.055,1.075,1.098,1.124)-1),0) -> 0 | AV6: =AJ6+V6 -> 24434 | AW6: =AK6+W6 -> 0 | AX6: =AL6+X6 -> 0 | AY6: =AM6+Y6 -> 8753 | AZ6: =AN6+Z6 -> 12216 | BA6: =AO6+AA6 -> 0 | BB6: =AP6+AB6 -> 0 | BC6: =AQ6+AC6 -> 12216 | ... BG6: =AU6+AG6 -> 0 | BH6: =AH6 -> 0 | BI6: =AI6 -> 0 | BJ6: =IFERROR(INDEX(装备库!$A$1:$Z$2022,MATCH($N6,装备库!$E$1:$E$2022,0),COLUMN(装备库!$D$1)),0) -> 41400 | BK6: =IF(P6=8,2,1.8) -> 1.8 | BL6: 1 | BM6: =ROUND(BJ6*BK6*BL6,0) -> 74520 | BN6: =ROUND(BM6*(CHOOSE($Q6+1,1,1.005,1.013,1.024,1.038,1.055,1.075,1.098,1.124)-1),0) -> 5589
A7: =IFERROR(INDEX(装备库!$A$2:$E$2022,MATCH(ROW()-1,装备库!$AK$2:$AK$2022,0),COLUMN()),"") -> 暗器 | B7: =IFERROR(INDEX(装备库!$A$2:$E$2022,MATCH(ROW()-1,装备库!$AK$2:$AK$2022,0),COLUMN()),"") -> 6_41292 | C7: =IFERROR(INDEX(装备库!$A$2:$E$2022,MATCH(ROW()-1,装备库!$AK$2:$AK$2022,0),5),"") -> 焚膏继晷(30200招无) | E7: 6 | G7: =ROW() -> 7 | H7: 上衣 | I7: =IFERROR(MATCH(H7,$A$2:$A$2000,0),I6) -> 354 | J7: =COUNTIF($A$2:$A$2665,H7) -> 28 | M7: 鞋子 | N7: =配装计算器!I12 -> 【门派套装】玄阙·燃炼鞋(41400破无) | O7: =IFERROR(1*$N$20,配装计算器!I13) -> 6 | P7: =IFERROR(INDEX(装备库!$A$1:$Z$2022,MATCH($N7,装备库!$E$1:$E$2022,0),COLUMN(装备库!$U$1)),0) -> 6 | Q7: =MIN(O7,P7) -> 6 | R7: =IF(IFERROR(INDEX(装备库!$A$1:$Z$2022,MATCH($N7,装备库!$E$1:$E$2022,0),COLUMN(装备库!W$1)),"")=0,"",IFERROR(INDEX(装备库!$A$1:$Z$2022,MATCH($N7,装备库!$E$1:$E$2022,0),COLUMN(装备库!W$1)),"")) -> 攻击孔 | S7: =IF(IFERROR(INDEX(装备库!$A$1:$Z$2022,MATCH($N7,装备库!$E$1:$E$2022,0),COLUMN(装备库!X$1)),"")=0,"",IFERROR(INDEX(装备库!$A$1:$Z$2022,MATCH($N7,装备库!$E$1:$E$2022,0),COLUMN(装备库!X$1)),"")) -> 破防孔 | T7: =IF(IFERROR(INDEX(装备库!$A$1:$Z$2022,MATCH($N7,装备库!$E$1:$E$2022,0),COLUMN(装备库!Y$1)),"")=0,"",IFERROR(INDEX(装备库!$A$1:$Z$2022,MATCH($N7,装备库!$E$1:$E$2022,0),COLUMN(装备库!Y$1)),"")) | U7: =IFERROR(INDEX(装备库!$A$1:$Z$2022,MATCH($N7,装备库!$E$1:$E$2022,0),COLUMN(装备库!$V$1)),"") -> 兑换牌 | V7: =IFERROR(INDEX(装备库!$A$1:$Z$2022,MATCH($N7,装备库!$E$1:$E$2022,0),COLUMN(装备库!F$1)),0) -> 15910 | W7: =IFERROR(INDEX(装备库!$A$1:$Z$2022,MATCH($N7,装备库!$E$1:$E$2022,0),COLUMN(装备库!G$1)),0) -> 1298 | X7: =IFERROR(INDEX(装备库!$A$1:$Z$2022,MATCH($N7,装备库!$E$1:$E$2022,0),COLUMN(装备库!H$1)),0) -> 0 | Y7: =IFERROR(INDEX(装备库!$A$1:$Z$2022,MATCH($N7,装备库!$E$1:$E$2022,0),COLUMN(装备库!I$1)),0) -> 2948 | Z7: =IFERROR(INDEX(装备库!$A$1:$Z$2022,MATCH($N7,装备库!$E$1:$E$2022,0),COLUMN(装备库!J$1)),0) -> 0 | AA7: =IFERROR(INDEX(装备库!$A$1:$Z$2022,MATCH($N7,装备库!$E$1:$E$2022,0),COLUMN(装备库!K$1)),0) -> 0 | AB7: =IFERROR(INDEX(装备库!$A$1:$Z$2022,MATCH($N7,装备库!$E$1:$E$2022,0),COLUMN(装备库!L$1)),0) -> 10848 | AC7: =IFERROR(INDEX(装备库!$A$1:$Z$2022,MATCH($N7,装备库!$E$1:$E$2022,0),COLUMN(装备库!M$1)),0) -> 0 | ... AI7: =IFERROR(INDEX(装备库!$A$1:$Z$2022,MATCH($N7,装备库!$E$1:$E$2022,0),COLUMN(装备库!S$1)),0) -> 0 | AJ7: =ROUND(V7*(CHOOSE($Q7+1,1,1.005,1.013,1.024,1.038,1.055,1.075,1.098,1.124)-1),0) -> 1193 | AK7: =ROUND(W7*(CHOOSE($Q7+1,1,1.005,1.013,1.024,1.038,1.055,1.075,1.098,1.124)-1),0) -> 97 | AL7: =ROUND(X7*(CHOOSE($Q7+1,1,1.005,1.013,1.024,1.038,1.055,1.075,1.098,1.124)-1),0) -> 0 | AM7: =ROUND(Y7*(CHOOSE($Q7+1,1,1.005,1.013,1.024,1.038,1.055,1.075,1.098,1.124)-1),0) -> 221 | AN7: =ROUND(Z7*(CHOOSE($Q7+1,1,1.005,1.013,1.024,1.038,1.055,1.075,1.098,1.124)-1),0) -> 0 | AO7: =ROUND(AA7*(CHOOSE($Q7+1,1,1.005,1.013,1.024,1.038,1.055,1.075,1.098,1.124)-1),0) -> 0 | AP7: =ROUND(AB7*(CHOOSE($Q7+1,1,1.005,1.013,1.024,1.038,1.055,1.075,1.098,1.124)-1),0) -> 814 | AQ7: =ROUND(AC7*(CHOOSE($Q7+1,1,1.005,1.013,1.024,1.038,1.055,1.075,1.098,1.124)-1),0) -> 0 | ... AU7: =ROUND(AG7*(CHOOSE($Q7+1,1,1.005,1.013,1.024,1.038,1.055,1.075,1.098,1.124)-1),0) -> 0 | AV7: =AJ7+V7 -> 17103 | AW7: =AK7+W7 -> 1395 | AX7: =AL7+X7 -> 0 | AY7: =AM7+Y7 -> 3169 | AZ7: =AN7+Z7 -> 0 | BA7: =AO7+AA7 -> 0 | BB7: =AP7+AB7 -> 11662 | BC7: =AQ7+AC7 -> 0 | ... BG7: =AU7+AG7 -> 0 | BH7: =AH7 -> 0 | BI7: =AI7 -> 0 | BJ7: =IFERROR(INDEX(装备库!$A$1:$Z$2022,MATCH($N7,装备库!$E$1:$E$2022,0),COLUMN(装备库!$D$1)),0) -> 41400 | BK7: =IF(P7=8,2,1.8) -> 1.8 | BL7: 0.7 | BM7: =ROUND(BJ7*BK7*BL7,0) -> 52164 | BN7: =ROUND(BM7*(CHOOSE($Q7+1,1,1.005,1.013,1.024,1.038,1.055,1.075,1.098,1.124)-1),0) -> 3912
A8: =IFERROR(INDEX(装备库!$A$2:$E$2022,MATCH(ROW()-1,装备库!$AK$2:$AK$2022,0),COLUMN()),"") -> 暗器 | B8: =IFERROR(INDEX(装备库!$A$2:$E$2022,MATCH(ROW()-1,装备库!$AK$2:$AK$2022,0),COLUMN()),"") -> 6_40933 | C8: =IFERROR(INDEX(装备库!$A$2:$E$2022,MATCH(ROW()-1,装备库!$AK$2:$AK$2022,0),5),"") -> 润源囊(30200速无) | E8: 7 | G8: =ROW() -> 8 | H8: 项链 | I8: =IFERROR(MATCH(H8,$A$2:$A$2000,0),I7) -> 382 | J8: =COUNTIF($A$2:$A$2665,H8) -> 38 | M8: 项链 | N8: =配装计算器!C17 -> 无修链·外·地(35300特效精简破无) | O8: =IFERROR(1*$N$20,配装计算器!C18) -> 6 | P8: =IFERROR(INDEX(装备库!$A$1:$Z$2022,MATCH($N8,装备库!$E$1:$E$2022,0),COLUMN(装备库!$U$1)),0) -> 6 | Q8: =MIN(O8,P8) -> 6 | R8: =IF(IFERROR(INDEX(装备库!$A$1:$Z$2022,MATCH($N8,装备库!$E$1:$E$2022,0),COLUMN(装备库!W$1)),"")=0,"",IFERROR(INDEX(装备库!$A$1:$Z$2022,MATCH($N8,装备库!$E$1:$E$2022,0),COLUMN(装备库!W$1)),"")) -> 破招孔 | S8: =IF(IFERROR(INDEX(装备库!$A$1:$Z$2022,MATCH($N8,装备库!$E$1:$E$2022,0),COLUMN(装备库!X$1)),"")=0,"",IFERROR(INDEX(装备库!$A$1:$Z$2022,MATCH($N8,装备库!$E$1:$E$2022,0),COLUMN(装备库!X$1)),"")) -> 破招孔 | T8: =IF(IFERROR(INDEX(装备库!$A$1:$Z$2022,MATCH($N8,装备库!$E$1:$E$2022,0),COLUMN(装备库!Y$1)),"")=0,"",IFERROR(INDEX(装备库!$A$1:$Z$2022,MATCH($N8,装备库!$E$1:$E$2022,0),COLUMN(装备库!Y$1)),"")) | U8: =IFERROR(INDEX(装备库!$A$1:$Z$2022,MATCH($N8,装备库!$E$1:$E$2022,0),COLUMN(装备库!$V$1)),"") -> 活动 | V8: =IFERROR(INDEX(装备库!$A$1:$Z$2022,MATCH($N8,装备库!$E$1:$E$2022,0),COLUMN(装备库!F$1)),0) -> 9690 | W8: =IFERROR(INDEX(装备库!$A$1:$Z$2022,MATCH($N8,装备库!$E$1:$E$2022,0),COLUMN(装备库!G$1)),0) -> 0 | X8: =IFERROR(INDEX(装备库!$A$1:$Z$2022,MATCH($N8,装备库!$E$1:$E$2022,0),COLUMN(装备库!H$1)),0) -> 0 | Y8: =IFERROR(INDEX(装备库!$A$1:$Z$2022,MATCH($N8,装备库!$E$1:$E$2022,0),COLUMN(装备库!I$1)),0) -> 2873 | Z8: =IFERROR(INDEX(装备库!$A$1:$Z$2022,MATCH($N8,装备库!$E$1:$E$2022,0),COLUMN(装备库!J$1)),0) -> 0 | AA8: =IFERROR(INDEX(装备库!$A$1:$Z$2022,MATCH($N8,装备库!$E$1:$E$2022,0),COLUMN(装备库!K$1)),0) -> 0 | AB8: =IFERROR(INDEX(装备库!$A$1:$Z$2022,MATCH($N8,装备库!$E$1:$E$2022,0),COLUMN(装备库!L$1)),0) -> 4845 | AC8: =IFERROR(INDEX(装备库!$A$1:$Z$2022,MATCH($N8,装备库!$E$1:$E$2022,0),COLUMN(装备库!M$1)),0) -> 0 | ... AI8: =IFERROR(INDEX(装备库!$A$1:$Z$2022,MATCH($N8,装备库!$E$1:$E$2022,0),COLUMN(装备库!S$1)),0) -> 0 | AJ8: =ROUND(V8*(CHOOSE($Q8+1,1,1.005,1.013,1.024,1.038,1.055,1.075,1.098,1.124)-1),0) -> 727 | AK8: =ROUND(W8*(CHOOSE($Q8+1,1,1.005,1.013,1.024,1.038,1.055,1.075,1.098,1.124)-1),0) -> 0 | AL8: =ROUND(X8*(CHOOSE($Q8+1,1,1.005,1.013,1.024,1.038,1.055,1.075,1.098,1.124)-1),0) -> 0 | AM8: =ROUND(Y8*(CHOOSE($Q8+1,1,1.005,1.013,1.024,1.038,1.055,1.075,1.098,1.124)-1),0) -> 215 | AN8: =ROUND(Z8*(CHOOSE($Q8+1,1,1.005,1.013,1.024,1.038,1.055,1.075,1.098,1.124)-1),0) -> 0 | AO8: =ROUND(AA8*(CHOOSE($Q8+1,1,1.005,1.013,1.024,1.038,1.055,1.075,1.098,1.124)-1),0) -> 0 | AP8: =ROUND(AB8*(CHOOSE($Q8+1,1,1.005,1.013,1.024,1.038,1.055,1.075,1.098,1.124)-1),0) -> 363 | AQ8: =ROUND(AC8*(CHOOSE($Q8+1,1,1.005,1.013,1.024,1.038,1.055,1.075,1.098,1.124)-1),0) -> 0 | ... AU8: =ROUND(AG8*(CHOOSE($Q8+1,1,1.005,1.013,1.024,1.038,1.055,1.075,1.098,1.124)-1),0) -> 0 | AV8: =AJ8+V8 -> 10417 | AW8: =AK8+W8 -> 0 | AX8: =AL8+X8 -> 0 | AY8: =AM8+Y8 -> 3088 | AZ8: =AN8+Z8 -> 0 | BA8: =AO8+AA8 -> 0 | BB8: =AP8+AB8 -> 5208 | BC8: =AQ8+AC8 -> 0 | ... BG8: =AU8+AG8 -> 0 | BH8: =AH8 -> 0 | BI8: =AI8 -> 0 | BJ8: =IFERROR(INDEX(装备库!$A$1:$Z$2022,MATCH($N8,装备库!$E$1:$E$2022,0),COLUMN(装备库!$D$1)),0) -> 35300 | BK8: =IF(P8=8,2,1.8) -> 1.8 | BL8: 0.5 | BM8: =ROUND(BJ8*BK8*BL8,0) -> 31770 | BN8: =ROUND(BM8*(CHOOSE($Q8+1,1,1.005,1.013,1.024,1.038,1.055,1.075,1.098,1.124)-1),0) -> 2383
